Workbook
Name \a: #REF!
Name \a: #REF!
Name \c: #REF!
Name \c: #REF!
Name \f: '[1]TAB1-01P'!#REF!
Name \f: '[1]TAB1-01P'!#REF!
Name \i: '[1]TAB1-01P'!#REF!
Name \i: '[1]TAB1-01P'!#REF!
Name \P: #REF!
Name \P: #REF!
Name \s: '[1]TAB1-01P'!#REF!
Name \s: '[1]TAB1-01P'!#REF!
Name \w: '[1]TAB1-01P'!#REF!
Name \w: '[1]TAB1-01P'!#REF!
Name ___: #REF!
Name ___: #REF!
Name ___: #REF!
Name _________________________________________________________________________________________: #REF!
Name _________________________________________________________________________________________: #REF!
Name __________________________________________________________________________cto2: [2]!_p1
Name __________________________________________________________________________cto2: [2]!_p1
Name __________________________________________________________________________er1: [2]!_p1
Name __________________________________________________________________________er1: [2]!_p1
Name __________________________________________________________________________rr2: [2]!_p1
Name __________________________________________________________________________rr2: [2]!_p1
Name _______________________________________________bh1: [3]!__________________p1
Name _______________________________________________bh1: [3]!__________________p1
Name _______________________________________________bh2: [3]!__________________p1
Name _______________________________________________bh2: [3]!__________________p1
Name _______________________________________________bh3: [3]!__________________p1
Name _______________________________________________bh3: [3]!__________________p1
Name _______________________________________________bh4: [3]!__________________p1
Name _______________________________________________bh4: [3]!__________________p1
Name _______________________________________________bh5: [3]!__________________p1
Name _______________________________________________bh5: [3]!__________________p1
Name _______________________________________________bh6: [3]!__________________p1
Name _______________________________________________bh6: [3]!__________________p1
Name _______________________________________________bh7: [3]!__________________p1
Name _______________________________________________bh7: [3]!__________________p1
Name _______________________________________________bh8: [3]!__________________p1
Name _______________________________________________bh8: [3]!__________________p1
Name _______________________________________________bh9: [3]!__________________p1
Name _______________________________________________bh9: [3]!__________________p1
Name _______________________________________________rio1: [3]!__________________p1
Name _______________________________________________rio1: [3]!__________________p1
Name _______________________________________________rio2: [3]!__________________p1
Name _______________________________________________rio2: [3]!__________________p1
Name _______________________________________________rio3: [3]!__________________p1
Name _______________________________________________rio3: [3]!__________________p1
Name _______________________________________________rj1: [3]!__________________p1
Name _______________________________________________rj1: [3]!__________________p1
Name _______________________________________________rj2: [3]!__________________p1
Name _______________________________________________rj2: [3]!__________________p1
Name _______________________________________________rj3: [3]!__________________p1
Name _______________________________________________rj3: [3]!__________________p1
Name _______________________________________________rj4: [3]!__________________p1
Name _______________________________________________rj4: [3]!__________________p1
Name _______________________________________________rj5: [3]!__________________p1
Name _______________________________________________rj5: [3]!__________________p1
Name _______________________________________________rj6: [3]!__________________p1

Sheet Resumo do plano
B2: Resumo do plano
B4: Tipo de midia | C4: Valor líquido | D4: Share | E4: Impactos | F4: CPM View | H4: Ambiente | I4: Valor líquido | J4: Share | K4: Impactos | L4: CPM View | N4: Formato | O4: Valor líquido | P4: Share | Q4: Impactos | R4: CPM View | U4: Praça | V4: Valor líquido | W4: Share | X4: Impactos | Y4: CPM View | AA4: Exibidor | AB4: Valor líquido | AC4: Share | AD4: Impactos | AE4: CPM View
B5: Total | C5: =SUM(C6:C500) -> 0 | D5: =SUM(D6:D500) -> #DIV/0! | E5: =SUM(E6:E500) -> 0 | F5: =+C5/(E5/1000) -> #DIV/0! | H5: Total | I5: =SUM(I6:I500) -> 0 | J5: =SUM(J6:J500) -> #DIV/0! | K5: =SUM(K6:K500) -> 0 | L5: =+I5/(K5/1000) -> #DIV/0! | N5: Total | O5: =SUM(O6:O500) -> 0 | P5: =SUM(P6:P500) -> #DIV/0! | Q5: =SUM(Q6:Q500) -> 0 | R5: =+O5/(Q5/1000) -> #DIV/0! | U5: Total | V5: =SUM(V6:V500) -> 0 | W5: =SUM(W6:W500) -> #DIV/0! | X5: =SUM(X6:X500) -> 0 | Y5: =+V5/(X5/1000) -> #DIV/0! | AA5: Total | AB5: =SUM(AB6:AB500) -> 0 | AC5: =SUM(AC6:AC500) -> #DIV/0! | AD5: =SUM(AD6:AD500) -> 0 | AE5: =+AB5/(AD5/1000) -> #DIV/0!
B6: Digital | C6: =SUMIFS(OOH!CV:CV,OOH!R:R,'Resumo do plano'!B6) -> 0 | D6: =+C6/$C$5 -> #DIV/0! | E6: =SUMIFS(OOH!CX:CX,OOH!R:R,'Resumo do plano'!B6) -> 0 | F6: =+C6/(E6/1000) -> #DIV/0! | H6: {=_xlfn._xlws.SORT(_xlfn.UNIQUE(OOH!N3:N490))} -> 0 | I6: =SUMIFS(OOH!CV:CV,OOH!N:N,'Resumo do plano'!H6) -> 0 | J6: =+I6/$C$5 -> #DIV/0! | K6: =SUMIFS(OOH!CX:CX,OOH!N:N,'Resumo do plano'!H6) -> 0 | L6: =IFERROR(I6/(K6/1000),0) -> 0 | N6: {=_xlfn._xlws.SORT(_xlfn.UNIQUE(OOH!O3:O490))} -> Abrigo De Ônibus Estático | O6: =SUMIFS(OOH!CV:CV,OOH!O:O,'Resumo do plano'!N6) -> 0 | P6: =+O6/$C$5 -> #DIV/0! | Q6: =SUMIFS(OOH!CX:CX,OOH!O:O,'Resumo do plano'!N6) -> 0 | R6: =IFERROR(O6/(Q6/1000),0) -> 0 | T6: Praça 1 | U6: {=_xlfn._xlws.SORT(_xlfn.UNIQUE(OOH!L3:L490))} -> 0 | V6: =SUMIFS(OOH!CV:CV,OOH!L:L,'Resumo do plano'!U6) -> 0 | W6: =+V6/$C$5 -> #DIV/0! | X6: =SUMIFS(OOH!CX:CX,OOH!L:L,'Resumo do plano'!U6) -> 0 | Y6: =IFERROR(V6/(X6/1000),0) -> 0 | AA6: {=_xlfn._xlws.SORT(_xlfn.UNIQUE(OOH!M3:M490))} -> 0 | AB6: =SUMIFS(OOH!CV:CV,OOH!M:M,'Resumo do plano'!AA6) -> 0 | AC6: =+AB6/$C$5 -> #DIV/0! | AD6: =SUMIFS(OOH!CX:CX,OOH!M:M,'Resumo do plano'!AA6) -> 0 | AE6: =IFERROR(AB6/(AD6/1000),0) -> 0
B7: Estático | C7: =SUMIFS(OOH!CV:CV,OOH!R:R,'Resumo do plano'!B7) -> 0 | D7: =+C7/$C$5 -> #DIV/0! | E7: =SUMIFS(OOH!CX:CX,OOH!R:R,'Resumo do plano'!B7) -> 0 | F7: =+C7/(E7/1000) -> #DIV/0! | I7: =SUMIFS(OOH!CV:CV,OOH!N:N,'Resumo do plano'!H7) -> 0 | J7: =+I7/$C$5 -> #DIV/0! | K7: =SUMIFS(OOH!CX:CX,OOH!N:N,'Resumo do plano'!H7) -> 0 | L7: =IFERROR(I7/(K7/1000),0) -> 0 | N7: 0 | O7: =SUMIFS(OOH!CV:CV,OOH!O:O,'Resumo do plano'!N7) -> 0 | P7: =+O7/$C$5 -> #DIV/0! | Q7: =SUMIFS(OOH!CX:CX,OOH!O:O,'Resumo do plano'!N7) -> 0 | R7: =IFERROR(O7/(Q7/1000),0) -> 0 | T7: Praça 2 | V7: =SUMIFS(OOH!CV:CV,OOH!L:L,'Resumo do plano'!U7) -> 0 | W7: =+V7/$C$5 -> #DIV/0! | X7: =SUMIFS(OOH!CX:CX,OOH!L:L,'Resumo do plano'!U7) -> 0 | Y7: =IFERROR(V7/(X7/1000),0) -> 0 | AB7: =SUMIFS(OOH!CV:CV,OOH!M:M,'Resumo do plano'!AA7) -> 0 | AC7: =+AB7/$C$5 -> #DIV/0! | AD7: =SUMIFS(OOH!CX:CX,OOH!M:M,'Resumo do plano'!AA7) -> 0 | AE7: =IFERROR(AB7/(AD7/1000),0) -> 0
I8: =SUMIFS(OOH!CV:CV,OOH!N:N,'Resumo do plano'!H8) -> 0 | J8: =+I8/$C$5 -> #DIV/0! | K8: =SUMIFS(OOH!CX:CX,OOH!N:N,'Resumo do plano'!H8) -> 0 | L8: =IFERROR(I8/(K8/1000),0) -> 0 | O8: =SUMIFS(OOH!CV:CV,OOH!O:O,'Resumo do plano'!N8) -> 0 | P8: =+O8/$C$5 -> #DIV/0! | Q8: =SUMIFS(OOH!CX:CX,OOH!O:O,'Resumo do plano'!N8) -> 0 | R8: =IFERROR(O8/(Q8/1000),0) -> 0 | T8: Praça 3 | V8: =SUMIFS(OOH!CV:CV,OOH!L:L,'Resumo do plano'!U8) -> 0 | W8: =+V8/$C$5 -> #DIV/0! | X8: =SUMIFS(OOH!CX:CX,OOH!L:L,'Resumo do plano'!U8) -> 0 | Y8: =IFERROR(V8/(X8/1000),0) -> 0 | AB8: =SUMIFS(OOH!CV:CV,OOH!M:M,'Resumo do plano'!AA8) -> 0 | AC8: =+AB8/$C$5 -> #DIV/0! | AD8: =SUMIFS(OOH!CX:CX,OOH!M:M,'Resumo do plano'!AA8) -> 0 | AE8: =IFERROR(AB8/(AD8/1000),0) -> 0
I9: =SUMIFS(OOH!CV:CV,OOH!N:N,'Resumo do plano'!H9) -> 0 | J9: =+I9/$C$5 -> #DIV/0! | K9: =SUMIFS(OOH!CX:CX,OOH!N:N,'Resumo do plano'!H9) -> 0 | L9: =IFERROR(I9/(K9/1000),0) -> 0 | O9: =SUMIFS(OOH!CV:CV,OOH!O:O,'Resumo do plano'!N9) -> 0 | P9: =+O9/$C$5 -> #DIV/0! | Q9: =SUMIFS(OOH!CX:CX,OOH!O:O,'Resumo do plano'!N9) -> 0 | R9: =IFERROR(O9/(Q9/1000),0) -> 0 | T9: Praça 4 | V9: =SUMIFS(OOH!CV:CV,OOH!L:L,'Resumo do plano'!U9) -> 0 | W9: =+V9/$C$5 -> #DIV/0! | X9: =SUMIFS(OOH!CX:CX,OOH!L:L,'Resumo do plano'!U9) -> 0 | Y9: =IFERROR(V9/(X9/1000),0) -> 0 | AB9: =SUMIFS(OOH!CV:CV,OOH!M:M,'Resumo do plano'!AA9) -> 0 | AC9: =+AB9/$C$5 -> #DIV/0! | AD9: =SUMIFS(OOH!CX:CX,OOH!M:M,'Resumo do plano'!AA9) -> 0 | AE9: =IFERROR(AB9/(AD9/1000),0) -> 0
I10: =SUMIFS(OOH!CV:CV,OOH!N:N,'Resumo do plano'!H10) -> 0 | J10: =+I10/$C$5 -> #DIV/0! | K10: =SUMIFS(OOH!CX:CX,OOH!N:N,'Resumo do plano'!H10) -> 0 | L10: =IFERROR(I10/(K10/1000),0) -> 0 | O10: =SUMIFS(OOH!CV:CV,OOH!O:O,'Resumo do plano'!N10) -> 0 | P10: =+O10/$C$5 -> #DIV/0! | Q10: =SUMIFS(OOH!CX:CX,OOH!O:O,'Resumo do plano'!N10) -> 0 | R10: =IFERROR(O10/(Q10/1000),0) -> 0 | T10: Praça 5 | V10: =SUMIFS(OOH!CV:CV,OOH!L:L,'Resumo do plano'!U10) -> 0 | W10: =+V10/$C$5 -> #DIV/0! | X10: =SUMIFS(OOH!CX:CX,OOH!L:L,'Resumo do plano'!U10) -> 0 | Y10: =IFERROR(V10/(X10/1000),0) -> 0 | AB10: =SUMIFS(OOH!CV:CV,OOH!M:M,'Resumo do plano'!AA10) -> 0 | AC10: =+AB10/$C$5 -> #DIV/0! | AD10: =SUMIFS(OOH!CX:CX,OOH!M:M,'Resumo do plano'!AA10) -> 0 | AE10: =IFERROR(AB10/(AD10/1000),0) -> 0
I11: =SUMIFS(OOH!CV:CV,OOH!N:N,'Resumo do plano'!H11) -> 0 | J11: =+I11/$C$5 -> #DIV/0! | K11: =SUMIFS(OOH!CX:CX,OOH!N:N,'Resumo do plano'!H11) -> 0 | L11: =IFERROR(I11/(K11/1000),0) -> 0 | O11: =SUMIFS(OOH!CV:CV,OOH!O:O,'Resumo do plano'!N11) -> 0 | P11: =+O11/$C$5 -> #DIV/0! | Q11: =SUMIFS(OOH!CX:CX,OOH!O:O,'Resumo do plano'!N11) -> 0 | R11: =IFERROR(O11/(Q11/1000),0) -> 0 | T11: Praça 6 | V11: =SUMIFS(OOH!CV:CV,OOH!L:L,'Resumo do plano'!U11) -> 0 | W11: =+V11/$C$5 -> #DIV/0! | X11: =SUMIFS(OOH!CX:CX,OOH!L:L,'Resumo do plano'!U11) -> 0 | Y11: =IFERROR(V11/(X11/1000),0) -> 0 | AB11: =SUMIFS(OOH!CV:CV,OOH!M:M,'Resumo do plano'!AA11) -> 0 | AC11: =+AB11/$C$5 -> #DIV/0! | AD11: =SUMIFS(OOH!CX:CX,OOH!M:M,'Resumo do plano'!AA11) -> 0 | AE11: =IFERROR(AB11/(AD11/1000),0) -> 0
I12: =SUMIFS(OOH!CV:CV,OOH!N:N,'Resumo do plano'!H12) -> 0 | J12: =+I12/$C$5 -> #DIV/0! | K12: =SUMIFS(OOH!CX:CX,OOH!N:N,'Resumo do plano'!H12) -> 0 | L12: =IFERROR(I12/(K12/1000),0) -> 0 | O12: =SUMIFS(OOH!CV:CV,OOH!O:O,'Resumo do plano'!N12) -> 0 | P12: =+O12/$C$5 -> #DIV/0! | Q12: =SUMIFS(OOH!CX:CX,OOH!O:O,'Resumo do plano'!N12) -> 0 | R12: =IFERROR(O12/(Q12/1000),0) -> 0 | T12: Praça 7 | V12: =SUMIFS(OOH!CV:CV,OOH!L:L,'Resumo do plano'!U12) -> 0 | W12: =+V12/$C$5 -> #DIV/0! | X12: =SUMIFS(OOH!CX:CX,OOH!L:L,'Resumo do plano'!U12) -> 0 | Y12: =IFERROR(V12/(X12/1000),0) -> 0 | AB12: =SUMIFS(OOH!CV:CV,OOH!M:M,'Resumo do plano'!AA12) -> 0 | AC12: =+AB12/$C$5 -> #DIV/0! | AD12: =SUMIFS(OOH!CX:CX,OOH!M:M,'Resumo do plano'!AA12) -> 0 | AE12: =IFERROR(AB12/(AD12/1000),0) -> 0
I13: =SUMIFS(OOH!CV:CV,OOH!N:N,'Resumo do plano'!H13) -> 0 | J13: =+I13/$C$5 -> #DIV/0! | K13: =SUMIFS(OOH!CX:CX,OOH!N:N,'Resumo do plano'!H13) -> 0 | L13: =IFERROR(I13/(K13/1000),0) -> 0 | O13: =SUMIFS(OOH!CV:CV,OOH!O:O,'Resumo do plano'!N13) -> 0 | P13: =+O13/$C$5 -> #DIV/0! | Q13: =SUMIFS(OOH!CX:CX,OOH!O:O,'Resumo do plano'!N13) -> 0 | R13: =IFERROR(O13/(Q13/1000),0) -> 0 | T13: Praça 8 | V13: =SUMIFS(OOH!CV:CV,OOH!L:L,'Resumo do plano'!U13) -> 0 | W13: =+V13/$C$5 -> #DIV/0! | X13: =SUMIFS(OOH!CX:CX,OOH!L:L,'Resumo do plano'!U13) -> 0 | Y13: =IFERROR(V13/(X13/1000),0) -> 0 | AB13: =SUMIFS(OOH!CV:CV,OOH!M:M,'Resumo do plano'!AA13) -> 0 | AC13: =+AB13/$C$5 -> #DIV/0! | AD13: =SUMIFS(OOH!CX:CX,OOH!M:M,'Resumo do plano'!AA13) -> 0 | AE13: =IFERROR(AB13/(AD13/1000),0) -> 0
I14: =SUMIFS(OOH!CV:CV,OOH!N:N,'Resumo do plano'!H14) -> 0 | J14: =+I14/$C$5 -> #DIV/0! | K14: =SUMIFS(OOH!CX:CX,OOH!N:N,'Resumo do plano'!H14) -> 0 | L14: =IFERROR(I14/(K14/1000),0) -> 0 | O14: =SUMIFS(OOH!CV:CV,OOH!O:O,'Resumo do plano'!N14) -> 0 | P14: =+O14/$C$5 -> #DIV/0! | Q14: =SUMIFS(OOH!CX:CX,OOH!O:O,'Resumo do plano'!N14) -> 0 | R14: =IFERROR(O14/(Q14/1000),0) -> 0 | T14: Praça 9 | V14: =SUMIFS(OOH!CV:CV,OOH!L:L,'Resumo do plano'!U14) -> 0 | W14: =+V14/$C$5 -> #DIV/0! | X14: =SUMIFS(OOH!CX:CX,OOH!L:L,'Resumo do plano'!U14) -> 0 | Y14: =IFERROR(V14/(X14/1000),0) -> 0 | AB14: =SUMIFS(OOH!CV:CV,OOH!M:M,'Resumo do plano'!AA14) -> 0 | AC14: =+AB14/$C$5 -> #DIV/0! | AD14: =SUMIFS(OOH!CX:CX,OOH!M:M,'Resumo do plano'!AA14) -> 0 | AE14: =IFERROR(AB14/(AD14/1000),0) -> 0
I15: =SUMIFS(OOH!CV:CV,OOH!N:N,'Resumo do plano'!H15) -> 0 | J15: =+I15/$C$5 -> #DIV/0! | K15: =SUMIFS(OOH!CX:CX,OOH!N:N,'Resumo do plano'!H15) -> 0 | L15: =IFERROR(I15/(K15/1000),0) -> 0 | O15: =SUMIFS(OOH!CV:CV,OOH!O:O,'Resumo do plano'!N15) -> 0 | P15: =+O15/$C$5 -> #DIV/0! | Q15: =SUMIFS(OOH!CX:CX,OOH!O:O,'Resumo do plano'!N15) -> 0 | R15: =IFERROR(O15/(Q15/1000),0) -> 0 | T15: Praça 10 | V15: =SUMIFS(OOH!CV:CV,OOH!L:L,'Resumo do plano'!U15) -> 0 | W15: =+V15/$C$5 -> #DIV/0! | X15: =SUMIFS(OOH!CX:CX,OOH!L:L,'Resumo do plano'!U15) -> 0 | Y15: =IFERROR(V15/(X15/1000),0) -> 0 | AB15: =SUMIFS(OOH!CV:CV,OOH!M:M,'Resumo do plano'!AA15) -> 0 | AC15: =+AB15/$C$5 -> #DIV/0! | AD15: =SUMIFS(OOH!CX:CX,OOH!M:M,'Resumo do plano'!AA15) -> 0 | AE15: =IFERROR(AB15/(AD15/1000),0) -> 0
I16: =SUMIFS(OOH!CV:CV,OOH!N:N,'Resumo do plano'!H16) -> 0 | J16: =+I16/$C$5 -> #DIV/0! | K16: =SUMIFS(OOH!CX:CX,OOH!N:N,'Resumo do plano'!H16) -> 0 | L16: =IFERROR(I16/(K16/1000),0) -> 0 | O16: =SUMIFS(OOH!CV:CV,OOH!O:O,'Resumo do plano'!N16) -> 0 | P16: =+O16/$C$5 -> #DIV/0! | Q16: =SUMIFS(OOH!CX:CX,OOH!O:O,'Resumo do plano'!N16) -> 0 | R16: =IFERROR(O16/(Q16/1000),0) -> 0 | T16: Praça 11 | V16: =SUMIFS(OOH!CV:CV,OOH!L:L,'Resumo do plano'!U16) -> 0 | W16: =+V16/$C$5 -> #DIV/0! | X16: =SUMIFS(OOH!CX:CX,OOH!L:L,'Resumo do plano'!U16) -> 0 | Y16: =IFERROR(V16/(X16/1000),0) -> 0 | AB16: =SUMIFS(OOH!CV:CV,OOH!M:M,'Resumo do plano'!AA16) -> 0 | AC16: =+AB16/$C$5 -> #DIV/0! | AD16: =SUMIFS(OOH!CX:CX,OOH!M:M,'Resumo do plano'!AA16) -> 0 | AE16: =IFERROR(AB16/(AD16/1000),0) -> 0
I17: =SUMIFS(OOH!CV:CV,OOH!N:N,'Resumo do plano'!H17) -> 0 | J17: =+I17/$C$5 -> #DIV/0! | K17: =SUMIFS(OOH!CX:CX,OOH!N:N,'Resumo do plano'!H17) -> 0 | L17: =IFERROR(I17/(K17/1000),0) -> 0 | O17: =SUMIFS(OOH!CV:CV,OOH!O:O,'Resumo do plano'!N17) -> 0 | P17: =+O17/$C$5 -> #DIV/0! | Q17: =SUMIFS(OOH!CX:CX,OOH!O:O,'Resumo do plano'!N17) -> 0 | R17: =IFERROR(O17/(Q17/1000),0) -> 0 | T17: Praça 12 | V17: =SUMIFS(OOH!CV:CV,OOH!L:L,'Resumo do plano'!U17) -> 0 | W17: =+V17/$C$5 -> #DIV/0! | X17: =SUMIFS(OOH!CX:CX,OOH!L:L,'Resumo do plano'!U17) -> 0 | Y17: =IFERROR(V17/(X17/1000),0) -> 0 | AB17: =SUMIFS(OOH!CV:CV,OOH!M:M,'Resumo do plano'!AA17) -> 0 | AC17: =+AB17/$C$5 -> #DIV/0! | AD17: =SUMIFS(OOH!CX:CX,OOH!M:M,'Resumo do plano'!AA17) -> 0 | AE17: =IFERROR(AB17/(AD17/1000),0) -> 0
I18: =SUMIFS(OOH!CV:CV,OOH!N:N,'Resumo do plano'!H18) -> 0 | J18: =+I18/$C$5 -> #DIV/0! | K18: =SUMIFS(OOH!CX:CX,OOH!N:N,'Resumo do plano'!H18) -> 0 | L18: =IFERROR(I18/(K18/1000),0) -> 0 | O18: =SUMIFS(OOH!CV:CV,OOH!O:O,'Resumo do plano'!N18) -> 0 | P18: =+O18/$C$5 -> #DIV/0! | Q18: =SUMIFS(OOH!CX:CX,OOH!O:O,'Resumo do plano'!N18) -> 0 | R18: =IFERROR(O18/(Q18/1000),0) -> 0 | T18: Praça 13 | V18: =SUMIFS(OOH!CV:CV,OOH!L:L,'Resumo do plano'!U18) -> 0 | W18: =+V18/$C$5 -> #DIV/0! | X18: =SUMIFS(OOH!CX:CX,OOH!L:L,'Resumo do plano'!U18) -> 0 | Y18: =IFERROR(V18/(X18/1000),0) -> 0 | AB18: =SUMIFS(OOH!CV:CV,OOH!M:M,'Resumo do plano'!AA18) -> 0 | AC18: =+AB18/$C$5 -> #DIV/0! | AD18: =SUMIFS(OOH!CX:CX,OOH!M:M,'Resumo do plano'!AA18) -> 0 | AE18: =IFERROR(AB18/(AD18/1000),0) -> 0
I19: =SUMIFS(OOH!CV:CV,OOH!N:N,'Resumo do plano'!H19) -> 0 | J19: =+I19/$C$5 -> #DIV/0! | K19: =SUMIFS(OOH!CX:CX,OOH!N:N,'Resumo do plano'!H19) -> 0 | L19: =IFERROR(I19/(K19/1000),0) -> 0 | O19: =SUMIFS(OOH!CV:CV,OOH!O:O,'Resumo do plano'!N19) -> 0 | P19: =+O19/$C$5 -> #DIV/0! | Q19: =SUMIFS(OOH!CX:CX,OOH!O:O,'Resumo do plano'!N19) -> 0 | R19: =IFERROR(O19/(Q19/1000),0) -> 0 | T19: Praça 14 | V19: =SUMIFS(OOH!CV:CV,OOH!L:L,'Resumo do plano'!U19) -> 0 | W19: =+V19/$C$5 -> #DIV/0! | X19: =SUMIFS(OOH!CX:CX,OOH!L:L,'Resumo do plano'!U19) -> 0 | Y19: =IFERROR(V19/(X19/1000),0) -> 0 | AB19: =SUMIFS(OOH!CV:CV,OOH!M:M,'Resumo do plano'!AA19) -> 0 | AC19: =+AB19/$C$5 -> #DIV/0! | AD19: =SUMIFS(OOH!CX:CX,OOH!M:M,'Resumo do plano'!AA19) -> 0 | AE19: =IFERROR(AB19/(AD19/1000),0) -> 0
... I24: =SUMIFS(OOH!CV:CV,OOH!N:N,'Resumo do plano'!H24) -> 0 | J24: =+I24/$C$5 -> #DIV/0! | K24: =SUMIFS(OOH!CX:CX,OOH!N:N,'Resumo do plano'!H24) -> 0 | L24: =IFERROR(I24/(K24/1000),0) -> 0 | O24: =SUMIFS(OOH!CV:CV,OOH!O:O,'Resumo do plano'!N24) -> 0 | P24: =+O24/$C$5 -> #DIV/0! | Q24: =SUMIFS(OOH!CX:CX,OOH!O:O,'Resumo do plano'!N24) -> 0 | R24: =IFERROR(O24/(Q24/1000),0) -> 0 | T24: Praça 19 | V24: =SUMIFS(OOH!CV:CV,OOH!L:L,'Resumo do plano'!U24) -> 0 | W24: =+V24/$C$5 -> #DIV/0! | X24: =SUMIFS(OOH!CX:CX,OOH!L:L,'Resumo do plano'!U24) -> 0 | Y24: =IFERROR(V24/(X24/1000),0) -> 0 | AB24: =SUMIFS(OOH!CV:CV,OOH!M:M,'Resumo do plano'!AA24) -> 0 | AC24: =+AB24/$C$5 -> #DIV/0! | AD24: =SUMIFS(OOH!CX:CX,OOH!M:M,'Resumo do plano'!AA24) -> 0 | AE24: =IFERROR(AB24/(AD24/1000),0) -> 0
T25: Praça 20
T26: Praça 21
T27: Praça 22
T28: Praça 23
T29: Praça 24
T30: Praça 25
T31: Praça 26
T32: Praça 27
T33: Praça 28
T34: Praça 29
T35: Praça 30
T36: Praça 31
... T125: Praça 120

Sheet Parametros
B1: TIPO DE NEGOCIAÇÃO | E1: TIPO DE PERÍODO | F1: No. dias | H1: Exibidores | J1: Formato | K1: Grupo | L1: IPV | N1: Estado | O1: Cidade | Q1: Estado | S1: Tipos de midia | V1: Ambiente | W1: IPV | Z1: Tipo de plano | AB1: Mês | AC1: No. de dias | AE1: Targets por marca | AI1: Classif para P1A | AL1: Deflator de visibilidade | AM1: Coef
B2: Carta | C2: Faturável | E2: Bi-semana | F2: 14 | H2: JCDECAUX | J2: Abrigo De Ônibus Digital | K2: G5MD | L2: 0.6 | N2: GO | O2: ABADIA DE GOIÁS | Q2: SP | S2: Estático | V2: Via pública | Z2: Megabrands | AB2: 45658 | AC2: 31 | AL2: Baixa visibilidade | AM2: 0.25
B3: Compromisso | C3: Faturável | E3: Quinzenal | F3: 15 | H3: ELETROMIDIA | J3: Abrigo De Ônibus Estático | K3: G3ME | L3: 0.5 | N3: GO | O3: ABADIÂNIA | Q3: RJ | S3: Digital | V3: Academia | W3: 0.4 | Z3: Avulso M G | AB3: =EDATE(AB2,1) -> 45689 | AC3: 28 | AE3: CERVEJA MAINSTREAM | AF3: Brahma | AG3: AS ABCDE 18+ | AI3: Jcdecaux | AJ3: Jcdecaux | AL3: Média visibilidade | AM3: 0.5
B4: Avulso | C4: Faturável | E4: Semanal | F4: 7 | H4: CLEAR CHANNEL | J4: Abrigo De Ônibus Sequencial | K4: G3ME | L4: 0.5 | N4: SC | O4: ABELARDO LUZ | Q4: BH | S4: Itinerante | V4: Aeroporto | W4: 0.5 | Z4: Avulso P | AB4: =EDATE(AB3,1) -> 45717 | AC4: 31 | AE4: CERVEJA MAINSTREAM | AF4: Skol | AG4: AS CDE 18+ | AI4: Eletromidia | AJ4: Eletromidia | AL4: Moderada visibilidade | AM4: 0.75
B5: Pontos fixos | C5: Faturável | E5: 28 dias | F5: 28 | H5: MOVIE MIDIA | J5: Adesivação De Bloqueios | K5: G6 | L5: 0.15 | N5: PE | O5: ABREU E LIMA | Q5: MG | S5: Spot | V5: Agência Bancaria | W5: 0.4 | AB5: =EDATE(AB4,1) -> 45748 | AC5: 30 | AE5: CERVEJA PREMIUM | AF5: Stella Artois | AG5: AS ABC 25+ | AI5: Urbia | AJ5: Urbia | AL5: Alta visibilidade | AM5: 1
B6: Rateio | C6: Faturável | E6: Diária | F6: 1 | H6: MUDE | J6: Adesivação De Escada Rolante | K6: G6 | L6: 0.15 | N6: MA | O6: AÇAILÂNDIA | Q6: ES | V6: Bar | W6: 0.4 | AB6: =EDATE(AB5,1) -> 45778 | AC6: 31 | AE6: Bebida Mista | AF6: Beats | AG6: AS ABC 18-34 | AI6: Pacote empena RJ | AJ6: Pacote empena RJ
B7: Reaplicação compromisso | C7: Não faturável | E7: 26 dias | F7: 26 | H7: KALLAS | J7: Adesivação Externa Fingers | K7: G6 | L7: 0.15 | N7: SP | O7: ABREU E LIMA | Q7: PE | V7: Brt | W7: 0.15 | AB7: =EDATE(AB6,1) -> 45809 | AC7: 30 | AE7: CERVEJA PREMIUM | AF7: Corona | AG7: AS AB 18+ | AI7: Rateio SSA | AJ7: Rateio SSA
B8: Reaplicação carta | C8: Não faturável | E8: Mensal | F8: 30 | H8: URBIA | J8: Adesivação Interna Fingers | K8: G6 | L8: 0.15 | N8: RS | O8: AGRONOMIA | Q8: BA | V8: Centro Comercial | W8: 0.4 | AB8: =EDATE(AB7,1) -> 45839 | AC8: 31 | AE8: CERVEJA PREMIUM | AF8: Budweiser | AG8: AS ABC 18+ | AI8: Banka | AJ8: Pacote banka
B9: Reaplicação avulsa | C9: Não faturável | H9: NEOOH | J9: Adesivo | K9: G6 | L9: 0.15 | N9: SP | O9: ÁGUAS DE LINDÓIA | Q9: RS | V9: Clube | W9: 0.6 | AB9: =EDATE(AB8,1) -> 45870 | AC9: 31 | AE9: CERVEJA PREMIUM | AF9: Spaten | AG9: AS ABC 18+ | AI9: Demais OOH | AJ9: Demais OOH
B10: Reaplicação ESG | C10: Não faturável | H10: HEZAGONO | J10: Adesivo Fundo De Esteira | K10: G6 | L10: 0.15 | N10: SC | O10: ÁGUAS MORNAS | Q10: SC | V10: Comunidade | W10: 0.25 | AB10: =EDATE(AB9,1) -> 45901 | AC10: 30 | AE10: Refrigerante | AF10: Guaraná | AG10: AS ABCD 18+
B11: Rebate | C11: Não faturável | H11: HELLOO | J11: Adesivo Lateral | K11: G6 | L11: 0.15 | N11: BA | O11: ALAGOINHAS | Q11: PR | V11: Cptm | W11: 0.15 | AB11: =EDATE(AB10,1) -> 45931 | AC11: 30 | AF11: MIKES | AG11: AS ABC 18-34
B12: Bonificação | C12: Não faturável | H12: URBANA MIDIA | J12: Ambientação | K12: G6 | L12: 0.15 | N12: SP | O12: ALAMBARI | Q12: AC | V12: Edifício Comercial | W12: 0.75 | AB12: =EDATE(AB11,1) -> 45962 | AC12: 30 | AF12: BRUTAL | AG12: AS ABC 18-34
B13: Empenas RJ | C13: Faturável | H13: GRUPO CORUJA | J13: Backbus | K13: G4 | L13: 0.4 | N13: MG | O13: ALÉM PARAÍBA | Q13: AL | V13: Edifício Residencial | W13: 0.75 | AB13: =EDATE(AB12,1) -> 45992 | AC13: 31 | AF13: ZÉ DELIVERY | AG13: AS ABCDE 20-44
B14: Rateio SSA | C14: Não faturável | H14: NÓS | J14: Backlight | K14: G6 | L14: 0.15 | N14: GO | O14: ALEXÂNIA | Q14: AM | V14: Estabelecimento comercial | W14: 0.4 | AF14: TONICA | AG14: AS AB 25+
H15: RZK | J15: Backseat | K15: G6 | L15: 0.09 | N15: MG | O15: ALFENAS | Q15: AP | V15: Estadio e casas de show | W15: 0.4 | AF15: FUSION | AG15: AS ABCDE 18+
H16: WESUPEROOH | J16: Banca De Jornal Digital | K16: G5MD | L16: 0.6 | N16: PE | O16: ALIANÇA | Q16: CE | V16: Farmácia | W16: 0.4 | AF16: AMA | AG16: AS ABCDE 18+
H17: MULTIPLAN | J17: Banca De Jornal Estática | K17: G3ME | L17: 0.5 | N17: PR | O17: ALMIRANTE TAMANDARÉ | Q17: DF | V17: Hotel | W17: 0.6
H18: OOH BRASIL | J18: Banca Estação | K18: G6 | L18: 0.15 | N18: RS | O18: ALPESTRE | Q18: GO | V18: Loja de Conveniência | W18: 0.4
H19: PRISMA RJ | J19: Banner | K19: G6 | L19: 0.15 | N19: RS | O19: ALTO PETRÓPOLIS | Q19: MA | V19: Metrô | W19: 0.15
H20: REDE OUTLIGHT | J20: Banner De Led | K20: G6 | L20: 0.15 | N20: SP | O20: ALUMÍNIO | Q20: MS | V20: Monotrilho | W20: 0.15
H21: BANDEIRANTES | J21: Banner Digital | K21: G2D | L21: 0.788 | N21: RS | O21: ALVORADA | Q21: MT | V21: Padaria | W21: 0.4
H22: ALTO IMPACTO | J22: Biciletário Estático | K22: G3ME | L22: 0.5 | N22: SP | O22: AMERICANA | Q22: PA | V22: Parque | W22: 0.4
H23: CAPITAL MIDIA | J23: Big Adesivo | K23: G6 | L23: 0.15 | N23: SP | O23: AMPARO | Q23: PB | V23: Porto | W23: 0.15
H24: SINERGY | J24: Big Led | K24: G2D | L24: 0.788 | N24: PA | O24: ANANINDEUA | Q24: PI | V24: Praia | W24: 0.6
H25: RIOVERDE | J25: Big Mupi | K25: G2D | L25: 0.788 | N25: GO | O25: ANÁPOLIS | Q25: RN | V25: Restaurantes | W25: 0.4
H26: LACTOM | J26: Big Testeira | K26: G6 | L26: 0.15 | N26: RS | O26: ANCHIETA | Q26: RO | V26: Rodoviária | W26: 0.15
H27: TOMI | J27: Brt Envelopado | K27: G4 | L27: 0.4 | N27: MG | O27: ANDRADAS | Q27: RR | V27: Salão de Beleza / Barbearia | W27: 0.6
H28: RETAIL MEDIA | J28: Busdoor | K28: G4 | L28: 0.4 | N28: SP | O28: ANDRADINA | Q28: SE | V28: Saúde | W28: 0.4
H29: PRISMA - BELEM | J29: Caixa Dagua | K29: G1E | L29: 0.92 | N29: RJ | O29: ANGRA DOS REIS | Q29: TO | V29: Shopping | W29: 0.6
H30: I7 MÍDIA | J30: Caixa De Pizza | K30: G6 | L30: 0.15 | N30: PR | O30: ANTÔNIO OLINTO | V30: Supermercado | W30: 0.5
H31: WAM PLANEJAMENTO | J31: Cancela De Pedágio | K31: G2E | L31: 0.75 | N31: GO | O31: APARECIDA DE GOIÂNIA | V31: Supervia | W31: 0.15
H32: GRUPO SOOH | J32: Carro De Som | K32: G4 | L32: 0.4 | N32: SP | O32: APIAÍ | V32: Táxi / Carro Aplicativo | W32: 0.15
H33: ROTA MÍDIA | J33: Carrossel Esteiras De Bagagem | K33: G6 | L33: 0.15 | N33: PR | O33: APUCARANA | V33: Terminal Náutico | W33: 0.15
H34: FAVRETTO | J34: Circuito Air Mub | K34: G6 | L34: 0.15 | N34: MS | O34: AQUIDAUANA | V34: Terminal Urbano | W34: 0.15
H35: PIXEL MIDIA | J35: Circuito Digital Indoor | K35: G6 | L35: 0.15 | N35: CE | O35: AQUIRAZ | V35: Universidade | W35: 0.4
H36: MOBEES | J36: Circuito Digital + Icônico Circular | K36: G6 | L36: 0.15 | N36: SE | O36: ARACAJU | V36: Vlt | W36: 0.15
H37: ALINHARES | J37: Circuito Experiência | K37: G6 | L37: 0.15 | N37: CE | O37: ARACATI
H38: BIG DOOH | J38: Circuito Passarelas | K38: G6 | L38: 0.15 | N38: SP | O38: ARAÇATUBA
H39: COOHNECT | J39: Colunas | K39: G6 | L39: 0.15 | N39: GO | O39: ARAGUAPAZ
H40: RPMIDIA | J40: Conjunto De Vidro | K40: G6 | L40: 0.15 | N40: MG | O40: ARAGUARI
...

Sheet OOH
B1: Digitar | D1: Digitar | E1: Digitar | F1: Digitar | G1: Escolher | H1: Escolher | I1: Digitar | J1: Escolher | K1: Fórmula | L1: Escolher | M1: Escolher | N1: Escolher | O1: Escolher | P1: Digitar | Q1: Fórmula | R1: Escolher | S1: Digitar | T1: Fórmula | U1: Digitar | V1: Digitar | W1: Digitar | X1: Digitar | Y1: Fórmula | Z1: Fórmula | AA1: Digitar | AB1: Digitar | AC1: Digitar | AD1: Digitar | AE1: Digitar | AF1: Fórmula | AG1: Digitar | AH1: Digitar | AI1: Digitar não obrigat[orio | AJ1: Fórmula | AK1: Digitar | AL1: Digitar | AM1: Digitar | AN1: Digitar | AO1: Digitar | AP1: Digitar | AQ1: Digitar | AR1: Digitar | AS1: Digitar | AT1: Digitar | AU1: Digitar | AV1: Digitar | AW1: Digitar | AX1: Digitar | AY1: Digitar | AZ1: Digitar | BA1: Digitar | BB1: Digitar | BC1: Digitar | BD1: Digitar | BE1: Digitar | BF1: Digitar | BG1: Digitar | BH1: Digitar | BI1: Digitar | BJ1: Digitar | BK1: Digitar | BL1: Digitar | BM1: Digitar | BN1: Digitar | BO1: Digitar | BP1: Digitar | BQ1: Digitar | BR1: Digitar | BS1: Digitar | BT1: Digitar | BU1: Digitar | BV1: Digitar | BW1: Digitar | BX1: Digitar | BY1: Digitar | BZ1: Digitar | CA1: Digitar | CB1: Digitar | CC1: Digitar | CD1: Digitar | CE1: Digitar | CF1: Digitar | CG1: Digitar | CH1: Digitar | CI1: Digitar | CJ1: Digitar | CK1: Digitar | CL1: Fórmula | CM1: Fórmula | CN1: Digitar | CO1: Digitar | CP1: Digitar | CQ1: Fórmula | CR1: Fórmula | CS1: Digitar | CT1: Fórmula | CU1: Fórmula | CV1: Fórmula | CW1: Fórmula | CX1: Fórmula | CY1: Fórmula | DA1: Fórmula | DB1: Fórmula | DC1: Fórmula | DD1: Fórmula | DE1: Digitar | DH1: Digitar | DI1: Digitar | DJ1: Fórmula | DK1: Fórmula | DM1: Fórmula | DN1: Digitar | DO1: Digitar | DP1: Fórmula | DQ1: Digitar | DR1: Digitar | DS1: Digitar | DT1: Digitar | DU1: Fórmula | DW1: Fórmula | DY1: Digitar | DZ1: Digitar | EA1: Digitar | EB1: Fórmula | EC1: Fórmula | ED1: Fórmula | EE1: Fórmula | EF1: Fórmula | EG1: Fórmula | EH1: Fórmula | EI1: Fórmula | EJ1: Fórmula | EP1: JANEIRO | ET1: FEVEREIRO | EX1: MARÇO | FC1: ABRIL | FG1: MAIO | FL1: JUNHO | FP1: JULHO | FT1: AGOSTO | FY1: SETEMBRO | GC1: OUTUBRO | GG1: NOVEMBRO | GL1: DEZEMBRO
B2: STATUS DO JOB | C2: ID | D2: JOB | E2: Campanha | F2: Produto | G2: Classif para P1A Escolher manual Pacote SSA Empenas RJ | H2: TIPO DE NEGOCIAÇÃO | I2: Descrição Ex Pacote Lola, Pacote Carnaval | J2: GEO | K2: UF | L2: PRAÇA | M2: EXIBIDOR | N2: AMBIENTE | O2: FORMATO | P2: DESCRIÇÃO | Q2: GRUPO | R2: TIPO | S2: KV | T2: ESPECIFICAÇÕES | U2: Numero de SLOTS | V2: Especificações Digital inserções | W2: Especificações Digital secundagem | X2: Numero de horas disponíveis | Y2: Número máximo de inserções | Z2: Número de inserções compradas | AA2: Especificação Estático Largura | AB2: Especificação Estático Altura | AC2: Deflator de visibilidade (se estático) | AD2: TT DE PONTOS | AE2: PERIODO DA TABELA | AF2: NUMERO DE DIAS REFERENCIA | AG2: INÍCIO | AH2: TÉRMINO | AI2: PERÍODO | AJ2: No. dias Campanha Digitar manualmente caso períodos com intervalos | AK2: 46026 | AL2: =AK2+7 -> 46033 | AM2: =AL2+7 -> 46040 | AN2: =AM2+7 -> 46047 | AO2: =AN2+7 -> 46054 | AP2: =AO2+7 -> 46061 | AQ2: =AP2+7 -> 46068 | AR2: =AQ2+7 -> 46075 | AS2: =AR2+7 -> 46082 | ... CJ2: =CI2+7 -> 46383 | CK2: Divisor para cálculo de flight e face | CL2: TT Flights | CM2: TT Faces | CN2: Modelo de compra (faces ou flights) | CO2: Justficativa do valor tabela diferente / métrica OBRIGATÓRIO | CP2: Tabela ORIGINAL DO VEICULO | CQ2: TABELA Unitária | CR2: Tabela Total | CS2: % | CT2: Negociado | CU2: Total Negociado | CV2: Valor líquido | CW2: Faturavel ou NÃO faturável | CX2: Impacto IPV | CY2: CpView | DA2: PRODUÇÃO Finalização | DB2: PRODUÇÃO Impressão | DD2: Prazo de Pagamento | DE2: Tabela Vigente | DH2: QTD de formatos | DI2: QTD de layouts | DJ2: Valor unitário | DK2: Valor total | DM2: QTD faces | DN2: QTD de produções | DO2: Reserva Técnica (%) | DP2: QTD Faces para produção | DQ2: Largura (m) | DR2: Altura (m) | DS2: Valor Unitário (R$/face) | DT2: Valor Unitário (R$/m²) | DU2: Total Parcial (R$) | DV2: Custo de Instalação (R$) | DW2: Total Final (R$) | DY2: Base para cálculo | DZ2: Impacto se informação for Semanal | EA2: Impacto se informação for mensal | EB2: TT de Dias Campanha | EC2: Público/ local no período da campanha | ED2: Soma do TT locais OU flights (p/ circuitos) | EE2: Fluxo de passantes | EF2: IPV ajustado | EG2: Impacto IPV | EH2: IPV Original | EI2: % inserções compradas / disponíveis | EJ2: Deflator de visibilidade - somente estáticos | EP2: W1 | EQ2: W2 | ER2: W3 | ES2: W4 | ET2: W5 | EU2: W6 | EV2: W7 | EW2: W8 | EX2: W9 | EY2: W10 | EZ2: W11 | FA2: W12 | FB2: W13 | FC2: W14 | FD2: W15 | FE2: W16 | FF2: W17 | FG2: W18 | FH2: W19 | FI2: W20 | FJ2: W21 | FK2: W22 | FL2: W23 | FM2: W24 | FN2: W25 | FO2: W26 | FP2: W27 | FQ2: W28 | FR2: W29 | FS2: W30 | FT2: W31 | FU2: W32 | FV2: W33 | FW2: W34 | FX2: W35 | FY2: W36 | FZ2: W37 | GA2: W38 | GB2: W39 | GC2: W40 | GD2: W41 | GE2: W42 | GF2: W43 | GG2: W44 | GH2: W45 | GI2: W46 | GJ2: W47 | GK2: W48 | GL2: W49 | GM2: W50 | GN2: W51 | GO2: W52 | GQ2: JAN | GR2: FEV | GS2: MAR | GT2: ABR | GU2: MAI | GV2: JUN | GW2: JUL | GX2: AGO | GY2: SET | GZ2: OUT | HA2: NOV | HB2: DEZ
C3: 1 | D3: 0 | E3: 0 | F3: 0 | G3: =IF(M3="","",IF(ISERROR(VLOOKUP(M3,Parametros!AI:AJ,2,0)),"Demais OOH",VLOOKUP(M3,Parametros!AI:AJ,2,0))) | J3: =IFERROR(VLOOKUP(K3,'GEOS AMBEV'!B:C,2,0),"") | K3: =_xlfn.XLOOKUP(L3,POPULAÇÃO!D:D,POPULAÇÃO!C:C) -> 0 | O3: Abrigo De Ônibus Estático | Q3: =IFERROR(VLOOKUP(O3,Parametros!J:K,2,0),"") -> G3ME | T3: =IF(R3="","",IF(R3="digital",W3&"""- "&V3&" ins/dia",TEXT(AA3,"0,00")&" x "&TEXT(AB3,"0,00")&"m")) | Y3: =IFERROR(86400/W3/24*X3,0) -> 0 | Z3: =+U3*V3 -> 0 | AF3: =IFERROR(VLOOKUP(AE3,Parametros!E:F,2,0),0) -> 0 | AJ3: =IF(AG3="","",AH3-AG3+1) | AK3: 40 | AL3: 40 | CK3: 1 | CL3: =IFERROR(COUNT(AK3:CJ3)/CK3,0) -> 2 | CM3: =IFERROR(SUM(AK3:CJ3)/CK3,0) -> 80 | CN3: Faces | CQ3: =IF(AE3="diária",CP3*AJ3*U3,IF(AJ3>AF3,CP3,AJ3/AF3*CP3)*U3) -> 0 | CR3: =IF(CN3="","0",IF(CN3="Faces",CQ3*CM3,CQ3*CL3)) -> 0 | CS3: 0.72 | CT3: =CP3*(1-CS3) -> 0 | CU3: =CR3*(1-CS3) -> 0 | CV3: =CU3*0.8 -> 0 | CW3: =IF(H3="","",IFERROR(VLOOKUP(H3,Parametros!B:C,2,0),0)) | CX3: =EG3 -> 0 | CY3: =IF(OR(CX3=0,CX3="Sem base de dados"),0,CV3/CX3*1000) -> 0 | DA3: =DK3 -> 0 | DB3: =DW3 -> 0 | DD3: =IF(AG3="",0,EDATE(DATE(YEAR(AG3),MONTH(AG3),1),5)) -> 0 | DE3: 2025 | DJ3: 800 | DK3: =DJ3*DI3*DH3 -> 0 | DM3: =IF(R3="Digital",0,IF(SUM(AK3:CJ3)=0,0,LARGE(AK3:CJ3,1))) -> 40 | DP3: =ROUNDUP(DN3*DM3*(1+DO3),0) -> 0 | DU3: =PRODUCT(DP3:DT3) -> 0 | DW3: =(DU3+DV3) -> 0 | DZ3: =SUMIFS('Mediana dos Impactos'!D:D,'Mediana dos Impactos'!C:C,OOH!O3,'Mediana dos Impactos'!B:B,OOH!L3) -> 0 | EB3: =AJ3 | EC3: =IFERROR(IF(DZ3<>"",DZ3/7*EB3,$EA3/30*EB3),0) -> 0 | ED3: =IF(DY3="",0,IF(DY3="Face",CM3,CL3)) -> 0 | EE3: =IF(DY3="Sem base de dados",DY3,EC3*ED3) -> 0 | EF3: =IF(R3="digital",(EI3*EH3),EJ3*EH3) -> 0 | EG3: =+EE3*EF3 -> 0 | EH3: =IFERROR(IF(N3="via pública",VLOOKUP($O3,Parametros!$J:$L,3,0),VLOOKUP(N3,Parametros!V:W,2,0)),0) -> 0 | EI3: =IFERROR(Z3/Y3,0) -> 0 | EJ3: =IFERROR(VLOOKUP(AC3,Parametros!AL:AM,2,0),1) -> 1 | EM3: =SUM(EP3:GO3) -> 0 | EN3: =EM3=CV3 -> TRUE | EP3: {=_xlfn.IFS(AK3="","",AK3,$CV3/$CM3/$CK3*AK3)} -> 0 | EQ3: {=_xlfn.IFS(AL3="","",AL3,$CV3/$CM3/$CK3*AL3)} -> 0 | ER3: {=_xlfn.IFS(AM3="","",AM3,$CV3/$CM3/$CK3*AM3)} | ES3: {=_xlfn.IFS(AN3="","",AN3,$CV3/$CM3/$CK3*AN3)} | ET3: {=_xlfn.IFS(AO3="","",AO3,$CV3/$CM3/$CK3*AO3)} | EU3: {=_xlfn.IFS(AP3="","",AP3,$CV3/$CM3/$CK3*AP3)} | EV3: {=_xlfn.IFS(AQ3="","",AQ3,$CV3/$CM3/$CK3*AQ3)} | EW3: {=_xlfn.IFS(AR3="","",AR3,$CV3/$CM3/$CK3*AR3)} | ... GO3: {=_xlfn.IFS(CJ3="","",CJ3,$CV3/$CM3/$CK3*CJ3)} | GQ3: =SUM(EP3:ES3) -> 0 | GR3: =SUM(ET3:EW3) -> 0 | GS3: =SUM(EX3:FB3) -> 0 | GT3: =SUM(FC3:FF3) -> 0 | GU3: =SUM(FG3:FK3) -> 0 | GV3: =SUM(FL3:FO3) -> 0 | GW3: =SUM(FP3:FS3) -> 0 | GX3: =SUM(FT3:FX3) -> 0 | GY3: =SUM(FY3:GB3) -> 0 | GZ3: =SUM(GC3:GF3) -> 0 | HA3: =SUM(GG3:GK3) -> 0 | HB3: =SUM(GL3:GO3) -> 0
C4: =+C3+1 -> 2 | D4: 0 | E4: 0 | F4: 0 | G4: =IF(M4="","",IF(ISERROR(VLOOKUP(M4,Parametros!AI:AJ,2,0)),"Demais OOH",VLOOKUP(M4,Parametros!AI:AJ,2,0))) | J4: =IFERROR(VLOOKUP(K4,'GEOS AMBEV'!B:C,2,0),"") | K4: =_xlfn.XLOOKUP(L4,POPULAÇÃO!D:D,POPULAÇÃO!C:C) -> 0 | Q4: =IFERROR(VLOOKUP(O4,Parametros!J:K,2,0),"") | T4: =IF(R4="","",IF(R4="digital",W4&"""- "&V4&" ins/dia",TEXT(AA4,"0,00")&" x "&TEXT(AB4,"0,00")&"m")) | Y4: =IFERROR(86400/W4/24*X4,0) -> 0 | Z4: =+U4*V4 -> 0 | AF4: =IFERROR(VLOOKUP(AE4,Parametros!E:F,2,0),0) -> 0 | AJ4: =IF(AG4="","",AH4-AG4+1) | CL4: =IFERROR(COUNT(AK4:CJ4)/CK4,0) -> 0 | CM4: =IFERROR(SUM(AK4:CJ4)/CK4,0) -> 0 | CQ4: =IF(AE4="diária",CP4*AJ4*U4,IF(AJ4>AF4,CP4,AJ4/AF4*CP4)*U4) -> 0 | CR4: =IF(CN4="","0",IF(CN4="Faces",CQ4*CM4,CQ4*CL4)) -> 0 | CS4: 0.72 | CT4: =CP4*(1-CS4) -> 0 | CU4: =CR4*(1-CS4) -> 0 | CV4: =CU4*0.8 -> 0 | CW4: =IF(H4="","",IFERROR(VLOOKUP(H4,Parametros!B:C,2,0),0)) | CX4: =EG4 -> 0 | CY4: =IF(OR(CX4=0,CX4="Sem base de dados"),0,CV4/CX4*1000) -> 0 | DA4: =DK4 -> 0 | DB4: =DW4 -> 0 | DD4: =IF(AG4="",0,EDATE(DATE(YEAR(AG4),MONTH(AG4),1),5)) -> 0 | DE4: 2025 | DJ4: 800 | DK4: =DJ4*DI4*DH4 -> 0 | DM4: =IF(R4="Digital",0,IF(SUM(AK4:CJ4)=0,0,LARGE(AK4:CJ4,1))) -> 0 | DP4: =ROUNDUP(DN4*DM4*(1+DO4),0) -> 0 | DU4: =PRODUCT(DP4:DT4) -> 0 | DW4: =(DU4+DV4) -> 0 | DZ4: =SUMIFS('Mediana dos Impactos'!D:D,'Mediana dos Impactos'!C:C,OOH!O4,'Mediana dos Impactos'!B:B,OOH!L4) -> 0 | EB4: =AJ4 | EC4: =IFERROR(IF(DZ4<>"",DZ4/7*EB4,$EA4/30*EB4),0) -> 0 | ED4: =IF(DY4="",0,IF(DY4="Face",CM4,CL4)) -> 0 | EE4: =IF(DY4="Sem base de dados",DY4,EC4*ED4) -> 0 | EF4: =IF(R4="digital",(EI4*EH4),EJ4*EH4) -> 0 | EG4: =+EE4*EF4 -> 0 | EH4: =IFERROR(IF(N4="via pública",VLOOKUP($O4,Parametros!$J:$L,3,0),VLOOKUP(N4,Parametros!V:W,2,0)),0) -> 0 | EI4: =IFERROR(Z4/Y4,0) -> 0 | EJ4: =IFERROR(VLOOKUP(AC4,Parametros!AL:AM,2,0),1) -> 1 | EM4: =SUM(EP4:GO4) -> 0 | EN4: =EM4=CV4 -> TRUE | EP4: {=_xlfn.IFS(AK4="","",AK4,$CV4/$CM4/$CK4*AK4)} | EQ4: {=_xlfn.IFS(AL4="","",AL4,$CV4/$CM4/$CK4*AL4)} | ER4: {=_xlfn.IFS(AM4="","",AM4,$CV4/$CM4/$CK4*AM4)} | ES4: {=_xlfn.IFS(AN4="","",AN4,$CV4/$CM4/$CK4*AN4)} | ET4: {=_xlfn.IFS(AO4="","",AO4,$CV4/$CM4/$CK4*AO4)} | EU4: {=_xlfn.IFS(AP4="","",AP4,$CV4/$CM4/$CK4*AP4)} | EV4: {=_xlfn.IFS(AQ4="","",AQ4,$CV4/$CM4/$CK4*AQ4)} | EW4: {=_xlfn.IFS(AR4="","",AR4,$CV4/$CM4/$CK4*AR4)} | ... GO4: {=_xlfn.IFS(CJ4="","",CJ4,$CV4/$CM4/$CK4*CJ4)} | GQ4: =SUM(EP4:ES4) -> 0 | GR4: =SUM(ET4:EW4) -> 0 | GS4: =SUM(EX4:FB4) -> 0 | GT4: =SUM(FC4:FF4) -> 0 | GU4: =SUM(FG4:FK4) -> 0 | GV4: =SUM(FL4:FO4) -> 0 | GW4: =SUM(FP4:FS4) -> 0 | GX4: =SUM(FT4:FX4) -> 0 | GY4: =SUM(FY4:GB4) -> 0 | GZ4: =SUM(GC4:GF4) -> 0 | HA4: =SUM(GG4:GK4) -> 0 | HB4: =SUM(GL4:GO4) -> 0
C5: =+C4+1 -> 3 | D5: 0 | E5: 0 | F5: 0 | G5: =IF(M5="","",IF(ISERROR(VLOOKUP(M5,Parametros!AI:AJ,2,0)),"Demais OOH",VLOOKUP(M5,Parametros!AI:AJ,2,0))) | J5: =IFERROR(VLOOKUP(K5,'GEOS AMBEV'!B:C,2,0),"") | K5: =_xlfn.XLOOKUP(L5,POPULAÇÃO!D:D,POPULAÇÃO!C:C) -> 0 | Q5: =IFERROR(VLOOKUP(O5,Parametros!J:K,2,0),"") | T5: =IF(R5="","",IF(R5="digital",W5&"""- "&V5&" ins/dia",TEXT(AA5,"0,00")&" x "&TEXT(AB5,"0,00")&"m")) | Y5: =IFERROR(86400/W5/24*X5,0) -> 0 | Z5: =+U5*V5 -> 0 | AF5: =IFERROR(VLOOKUP(AE5,Parametros!E:F,2,0),0) -> 0 | AJ5: =IF(AG5="","",AH5-AG5+1) | CL5: =IFERROR(COUNT(AK5:CJ5)/CK5,0) -> 0 | CM5: =IFERROR(SUM(AK5:CJ5)/CK5,0) -> 0 | CQ5: =IF(AE5="diária",CP5*AJ5*U5,IF(AJ5>AF5,CP5,AJ5/AF5*CP5)*U5) -> 0 | CR5: =IF(CN5="","0",IF(CN5="Faces",CQ5*CM5,CQ5*CL5)) -> 0 | CS5: 0.72 | CT5: =CP5*(1-CS5) -> 0 | CU5: =CR5*(1-CS5) -> 0 | CV5: =CU5*0.8 -> 0 | CW5: =IF(H5="","",IFERROR(VLOOKUP(H5,Parametros!B:C,2,0),0)) | CX5: =EG5 -> 0 | CY5: =IF(OR(CX5=0,CX5="Sem base de dados"),0,CV5/CX5*1000) -> 0 | DA5: =DK5 -> 0 | DB5: =DW5 -> 0 | DD5: =IF(AG5="",0,EDATE(DATE(YEAR(AG5),MONTH(AG5),1),5)) -> 0 | DE5: 2025 | DJ5: 800 | DK5: =DJ5*DI5*DH5 -> 0 | DM5: =IF(R5="Digital",0,IF(SUM(AK5:CJ5)=0,0,LARGE(AK5:CJ5,1))) -> 0 | DP5: =ROUNDUP(DN5*DM5*(1+DO5),0) -> 0 | DU5: =PRODUCT(DP5:DT5) -> 0 | DW5: =(DU5+DV5) -> 0 | DZ5: =SUMIFS('Mediana dos Impactos'!D:D,'Mediana dos Impactos'!C:C,OOH!O5,'Mediana dos Impactos'!B:B,OOH!L5) -> 0 | EB5: =AJ5 | EC5: =IFERROR(IF(DZ5<>"",DZ5/7*EB5,$EA5/30*EB5),0) -> 0 | ED5: =IF(DY5="",0,IF(DY5="Face",CM5,CL5)) -> 0 | EE5: =IF(DY5="Sem base de dados",DY5,EC5*ED5) -> 0 | EF5: =IF(R5="digital",(EI5*EH5),EJ5*EH5) -> 0 | EG5: =+EE5*EF5 -> 0 | EH5: =IFERROR(IF(N5="via pública",VLOOKUP($O5,Parametros!$J:$L,3,0),VLOOKUP(N5,Parametros!V:W,2,0)),0) -> 0 | EI5: =IFERROR(Z5/Y5,0) -> 0 | EJ5: =IFERROR(VLOOKUP(AC5,Parametros!AL:AM,2,0),1) -> 1 | EM5: =SUM(EP5:GO5) -> 0 | EN5: =EM5=CV5 -> TRUE | EP5: {=_xlfn.IFS(AK5="","",AK5,$CV5/$CM5/$CK5*AK5)} | EQ5: {=_xlfn.IFS(AL5="","",AL5,$CV5/$CM5/$CK5*AL5)} | ER5: {=_xlfn.IFS(AM5="","",AM5,$CV5/$CM5/$CK5*AM5)} | ES5: {=_xlfn.IFS(AN5="","",AN5,$CV5/$CM5/$CK5*AN5)} | ET5: {=_xlfn.IFS(AO5="","",AO5,$CV5/$CM5/$CK5*AO5)} | EU5: {=_xlfn.IFS(AP5="","",AP5,$CV5/$CM5/$CK5*AP5)} | EV5: {=_xlfn.IFS(AQ5="","",AQ5,$CV5/$CM5/$CK5*AQ5)} | EW5: {=_xlfn.IFS(AR5="","",AR5,$CV5/$CM5/$CK5*AR5)} | ... GO5: {=_xlfn.IFS(CJ5="","",CJ5,$CV5/$CM5/$CK5*CJ5)} | GQ5: =SUM(EP5:ES5) -> 0 | GR5: =SUM(ET5:EW5) -> 0 | GS5: =SUM(EX5:FB5) -> 0 | GT5: =SUM(FC5:FF5) -> 0 | GU5: =SUM(FG5:FK5) -> 0 | GV5: =SUM(FL5:FO5) -> 0 | GW5: =SUM(FP5:FS5) -> 0 | GX5: =SUM(FT5:FX5) -> 0 | GY5: =SUM(FY5:GB5) -> 0 | GZ5: =SUM(GC5:GF5) -> 0 | HA5: =SUM(GG5:GK5) -> 0 | HB5: =SUM(GL5:GO5) -> 0
C6: =+C5+1 -> 4 | D6: 0 | E6: 0 | F6: 0 | G6: =IF(M6="","",IF(ISERROR(VLOOKUP(M6,Parametros!AI:AJ,2,0)),"Demais OOH",VLOOKUP(M6,Parametros!AI:AJ,2,0))) | J6: =IFERROR(VLOOKUP(K6,'GEOS AMBEV'!B:C,2,0),"") | K6: =_xlfn.XLOOKUP(L6,POPULAÇÃO!D:D,POPULAÇÃO!C:C) -> 0 | Q6: =IFERROR(VLOOKUP(O6,Parametros!J:K,2,0),"") | T6: =IF(R6="","",IF(R6="digital",W6&"""- "&V6&" ins/dia",TEXT(AA6,"0,00")&" x "&TEXT(AB6,"0,00")&"m")) | Y6: =IFERROR(86400/W6/24*X6,0) -> 0 | Z6: =+U6*V6 -> 0 | AF6: =IFERROR(VLOOKUP(AE6,Parametros!E:F,2,0),0) -> 0 | AJ6: =IF(AG6="","",AH6-AG6+1) | CL6: =IFERROR(COUNT(AK6:CJ6)/CK6,0) -> 0 | CM6: =IFERROR(SUM(AK6:CJ6)/CK6,0) -> 0 | CQ6: =IF(AE6="diária",CP6*AJ6*U6,IF(AJ6>AF6,CP6,AJ6/AF6*CP6)*U6) -> 0 | CR6: =IF(CN6="","0",IF(CN6="Faces",CQ6*CM6,CQ6*CL6)) -> 0 | CS6: 0.72 | CT6: =CP6*(1-CS6) -> 0 | CU6: =CR6*(1-CS6) -> 0 | CV6: =CU6*0.8 -> 0 | CW6: =IF(H6="","",IFERROR(VLOOKUP(H6,Parametros!B:C,2,0),0)) | CX6: =EG6 -> 0 | CY6: =IF(OR(CX6=0,CX6="Sem base de dados"),0,CV6/CX6*1000) -> 0 | DA6: =DK6 -> 0 | DB6: =DW6 -> 0 | DD6: =IF(AG6="",0,EDATE(DATE(YEAR(AG6),MONTH(AG6),1),5)) -> 0 | DE6: 2025 | DJ6: 800 | DK6: =DJ6*DI6*DH6 -> 0 | DM6: =IF(R6="Digital",0,IF(SUM(AK6:CJ6)=0,0,LARGE(AK6:CJ6,1))) -> 0 | DP6: =ROUNDUP(DN6*DM6*(1+DO6),0) -> 0 | DU6: =PRODUCT(DP6:DT6) -> 0 | DW6: =(DU6+DV6) -> 0 | DZ6: =SUMIFS('Mediana dos Impactos'!D:D,'Mediana dos Impactos'!C:C,OOH!O6,'Mediana dos Impactos'!B:B,OOH!L6) -> 0 | EB6: =AJ6 | EC6: =IFERROR(IF(DZ6<>"",DZ6/7*EB6,$EA6/30*EB6),0) -> 0 | ED6: =IF(DY6="",0,IF(DY6="Face",CM6,CL6)) -> 0 | EE6: =IF(DY6="Sem base de dados",DY6,EC6*ED6) -> 0 | EF6: =IF(R6="digital",(EI6*EH6),EJ6*EH6) -> 0 | EG6: =+EE6*EF6 -> 0 | EH6: =IFERROR(IF(N6="via pública",VLOOKUP($O6,Parametros!$J:$L,3,0),VLOOKUP(N6,Parametros!V:W,2,0)),0) -> 0 | EI6: =IFERROR(Z6/Y6,0) -> 0 | EJ6: =IFERROR(VLOOKUP(AC6,Parametros!AL:AM,2,0),1) -> 1 | EM6: =SUM(EP6:GO6) -> 0 | EN6: =EM6=CV6 -> TRUE | EP6: {=_xlfn.IFS(AK6="","",AK6,$CV6/$CM6/$CK6*AK6)} | EQ6: {=_xlfn.IFS(AL6="","",AL6,$CV6/$CM6/$CK6*AL6)} | ER6: {=_xlfn.IFS(AM6="","",AM6,$CV6/$CM6/$CK6*AM6)} | ES6: {=_xlfn.IFS(AN6="","",AN6,$CV6/$CM6/$CK6*AN6)} | ET6: {=_xlfn.IFS(AO6="","",AO6,$CV6/$CM6/$CK6*AO6)} | EU6: {=_xlfn.IFS(AP6="","",AP6,$CV6/$CM6/$CK6*AP6)} | EV6: {=_xlfn.IFS(AQ6="","",AQ6,$CV6/$CM6/$CK6*AQ6)} | EW6: {=_xlfn.IFS(AR6="","",AR6,$CV6/$CM6/$CK6*AR6)} | ... GO6: {=_xlfn.IFS(CJ6="","",CJ6,$CV6/$CM6/$CK6*CJ6)} | GQ6: =SUM(EP6:ES6) -> 0 | GR6: =SUM(ET6:EW6) -> 0 | GS6: =SUM(EX6:FB6) -> 0 | GT6: =SUM(FC6:FF6) -> 0 | GU6: =SUM(FG6:FK6) -> 0 | GV6: =SUM(FL6:FO6) -> 0 | GW6: =SUM(FP6:FS6) -> 0 | GX6: =SUM(FT6:FX6) -> 0 | GY6: =SUM(FY6:GB6) -> 0 | GZ6: =SUM(GC6:GF6) -> 0 | HA6: =SUM(GG6:GK6) -> 0 | HB6: =SUM(GL6:GO6) -> 0
C7: =+C6+1 -> 5 | D7: 0 | E7: 0 | F7: 0 | G7: =IF(M7="","",IF(ISERROR(VLOOKUP(M7,Parametros!AI:AJ,2,0)),"Demais OOH",VLOOKUP(M7,Parametros!AI:AJ,2,0))) | J7: =IFERROR(VLOOKUP(K7,'GEOS AMBEV'!B:C,2,0),"") | K7: =_xlfn.XLOOKUP(L7,POPULAÇÃO!D:D,POPULAÇÃO!C:C) -> 0 | Q7: =IFERROR(VLOOKUP(O7,Parametros!J:K,2,0),"") | T7: =IF(R7="","",IF(R7="digital",W7&"""- "&V7&" ins/dia",TEXT(AA7,"0,00")&" x "&TEXT(AB7,"0,00")&"m")) | Y7: =IFERROR(86400/W7/24*X7,0) -> 0 | Z7: =+U7*V7 -> 0 | AF7: =IFERROR(VLOOKUP(AE7,Parametros!E:F,2,0),0) -> 0 | AJ7: =IF(AG7="","",AH7-AG7+1) | CL7: =IFERROR(COUNT(AK7:CJ7)/CK7,0) -> 0 | CM7: =IFERROR(SUM(AK7:CJ7)/CK7,0) -> 0 | CQ7: =IF(AE7="diária",CP7*AJ7*U7,IF(AJ7>AF7,CP7,AJ7/AF7*CP7)*U7) -> 0 | CR7: =IF(CN7="","0",IF(CN7="Faces",CQ7*CM7,CQ7*CL7)) -> 0 | CS7: 0.72 | CT7: =CP7*(1-CS7) -> 0 | CU7: =CR7*(1-CS7) -> 0 | CV7: =CU7*0.8 -> 0 | CW7: =IF(H7="","",IFERROR(VLOOKUP(H7,Parametros!B:C,2,0),0)) | CX7: =EG7 -> 0 | CY7: =IF(OR(CX7=0,CX7="Sem base de dados"),0,CV7/CX7*1000) -> 0 | DA7: =DK7 -> 0 | DB7: =DW7 -> 0 | DD7: =IF(AG7="",0,EDATE(DATE(YEAR(AG7),MONTH(AG7),1),5)) -> 0 | DE7: 2025 | DJ7: 800 | DK7: =DJ7*DI7*DH7 -> 0 | DM7: =IF(R7="Digital",0,IF(SUM(AK7:CJ7)=0,0,LARGE(AK7:CJ7,1))) -> 0 | DP7: =ROUNDUP(DN7*DM7*(1+DO7),0) -> 0 | DU7: =PRODUCT(DP7:DT7) -> 0 | DW7: =(DU7+DV7) -> 0 | DZ7: =SUMIFS('Mediana dos Impactos'!D:D,'Mediana dos Impactos'!C:C,OOH!O7,'Mediana dos Impactos'!B:B,OOH!L7) -> 0 | EB7: =AJ7 | EC7: =IFERROR(IF(DZ7<>"",DZ7/7*EB7,$EA7/30*EB7),0) -> 0 | ED7: =IF(DY7="",0,IF(DY7="Face",CM7,CL7)) -> 0 | EE7: =IF(DY7="Sem base de dados",DY7,EC7*ED7) -> 0 | EF7: =IF(R7="digital",(EI7*EH7),EJ7*EH7) -> 0 | EG7: =+EE7*EF7 -> 0 | EH7: =IFERROR(IF(N7="via pública",VLOOKUP($O7,Parametros!$J:$L,3,0),VLOOKUP(N7,Parametros!V:W,2,0)),0) -> 0 | EI7: =IFERROR(Z7/Y7,0) -> 0 | EJ7: =IFERROR(VLOOKUP(AC7,Parametros!AL:AM,2,0),1) -> 1 | EM7: =SUM(EP7:GO7) -> 0 | EN7: =EM7=CV7 -> TRUE | EP7: {=_xlfn.IFS(AK7="","",AK7,$CV7/$CM7/$CK7*AK7)} | EQ7: {=_xlfn.IFS(AL7="","",AL7,$CV7/$CM7/$CK7*AL7)} | ER7: {=_xlfn.IFS(AM7="","",AM7,$CV7/$CM7/$CK7*AM7)} | ES7: {=_xlfn.IFS(AN7="","",AN7,$CV7/$CM7/$CK7*AN7)} | ET7: {=_xlfn.IFS(AO7="","",AO7,$CV7/$CM7/$CK7*AO7)} | EU7: {=_xlfn.IFS(AP7="","",AP7,$CV7/$CM7/$CK7*AP7)} | EV7: {=_xlfn.IFS(AQ7="","",AQ7,$CV7/$CM7/$CK7*AQ7)} | EW7: {=_xlfn.IFS(AR7="","",AR7,$CV7/$CM7/$CK7*AR7)} | ... GO7: {=_xlfn.IFS(CJ7="","",CJ7,$CV7/$CM7/$CK7*CJ7)} | GQ7: =SUM(EP7:ES7) -> 0 | GR7: =SUM(ET7:EW7) -> 0 | GS7: =SUM(EX7:FB7) -> 0 | GT7: =SUM(FC7:FF7) -> 0 | GU7: =SUM(FG7:FK7) -> 0 | GV7: =SUM(FL7:FO7) -> 0 | GW7: =SUM(FP7:FS7) -> 0 | GX7: =SUM(FT7:FX7) -> 0 | GY7: =SUM(FY7:GB7) -> 0 | GZ7: =SUM(GC7:GF7) -> 0 | HA7: =SUM(GG7:GK7) -> 0 | HB7: =SUM(GL7:GO7) -> 0
C8: =+C7+1 -> 6 | D8: 0 | E8: 0 | F8: 0 | G8: =IF(M8="","",IF(ISERROR(VLOOKUP(M8,Parametros!AI:AJ,2,0)),"Demais OOH",VLOOKUP(M8,Parametros!AI:AJ,2,0))) | J8: =IFERROR(VLOOKUP(K8,'GEOS AMBEV'!B:C,2,0),"") | K8: =_xlfn.XLOOKUP(L8,POPULAÇÃO!D:D,POPULAÇÃO!C:C) -> 0 | Q8: =IFERROR(VLOOKUP(O8,Parametros!J:K,2,0),"") | T8: =IF(R8="","",IF(R8="digital",W8&"""- "&V8&" ins/dia",TEXT(AA8,"0,00")&" x "&TEXT(AB8,"0,00")&"m")) | Y8: =IFERROR(86400/W8/24*X8,0) -> 0 | Z8: =+U8*V8 -> 0 | AF8: =IFERROR(VLOOKUP(AE8,Parametros!E:F,2,0),0) -> 0 | AJ8: =IF(AG8="","",AH8-AG8+1) | CL8: =IFERROR(COUNT(AK8:CJ8)/CK8,0) -> 0 | CM8: =IFERROR(SUM(AK8:CJ8)/CK8,0) -> 0 | CQ8: =IF(AE8="diária",CP8*AJ8*U8,IF(AJ8>AF8,CP8,AJ8/AF8*CP8)*U8) -> 0 | CR8: =IF(CN8="","0",IF(CN8="Faces",CQ8*CM8,CQ8*CL8)) -> 0 | CS8: 0.65 | CT8: =CP8*(1-CS8) -> 0 | CU8: =CR8*(1-CS8) -> 0 | CV8: =CU8*0.8 -> 0 | CW8: =IF(H8="","",IFERROR(VLOOKUP(H8,Parametros!B:C,2,0),0)) | CX8: =EG8 -> 0 | CY8: =IF(OR(CX8=0,CX8="Sem base de dados"),0,CV8/CX8*1000) -> 0 | DA8: =DK8 -> 0 | DB8: =DW8 -> 0 | DD8: =IF(AG8="",0,EDATE(DATE(YEAR(AG8),MONTH(AG8),1),5)) -> 0 | DE8: 2025 | DJ8: 800 | DK8: =DJ8*DI8*DH8 -> 0 | DM8: =IF(R8="Digital",0,IF(SUM(AK8:CJ8)=0,0,LARGE(AK8:CJ8,1))) -> 0 | DP8: =ROUNDUP(DN8*DM8*(1+DO8),0) -> 0 | DU8: =PRODUCT(DP8:DT8) -> 0 | DW8: =(DU8+DV8) -> 0 | DZ8: =SUMIFS('Mediana dos Impactos'!D:D,'Mediana dos Impactos'!C:C,OOH!O8,'Mediana dos Impactos'!B:B,OOH!L8) -> 0 | EB8: =AJ8 | EC8: =IFERROR(IF(DZ8<>"",DZ8/7*EB8,$EA8/30*EB8),0) -> 0 | ED8: =IF(DY8="",0,IF(DY8="Face",CM8,CL8)) -> 0 | EE8: =IF(DY8="Sem base de dados",DY8,EC8*ED8) -> 0 | EF8: =IF(R8="digital",(EI8*EH8),EJ8*EH8) -> 0 | EG8: =+EE8*EF8 -> 0 | EH8: =IFERROR(IF(N8="via pública",VLOOKUP($O8,Parametros!$J:$L,3,0),VLOOKUP(N8,Parametros!V:W,2,0)),0) -> 0 | EI8: =IFERROR(Z8/Y8,0) -> 0 | EJ8: =IFERROR(VLOOKUP(AC8,Parametros!AL:AM,2,0),1) -> 1 | EM8: =SUM(EP8:GO8) -> 0 | EN8: =EM8=CV8 -> TRUE | EP8: {=_xlfn.IFS(AK8="","",AK8,$CV8/$CM8/$CK8*AK8)} | EQ8: {=_xlfn.IFS(AL8="","",AL8,$CV8/$CM8/$CK8*AL8)} | ER8: {=_xlfn.IFS(AM8="","",AM8,$CV8/$CM8/$CK8*AM8)} | ES8: {=_xlfn.IFS(AN8="","",AN8,$CV8/$CM8/$CK8*AN8)} | ET8: {=_xlfn.IFS(AO8="","",AO8,$CV8/$CM8/$CK8*AO8)} | EU8: {=_xlfn.IFS(AP8="","",AP8,$CV8/$CM8/$CK8*AP8)} | EV8: {=_xlfn.IFS(AQ8="","",AQ8,$CV8/$CM8/$CK8*AQ8)} | EW8: {=_xlfn.IFS(AR8="","",AR8,$CV8/$CM8/$CK8*AR8)} | ... GO8: {=_xlfn.IFS(CJ8="","",CJ8,$CV8/$CM8/$CK8*CJ8)} | GQ8: =SUM(EP8:ES8) -> 0 | GR8: =SUM(ET8:EW8) -> 0 | GS8: =SUM(EX8:FB8) -> 0 | GT8: =SUM(FC8:FF8) -> 0 | GU8: =SUM(FG8:FK8) -> 0 | GV8: =SUM(FL8:FO8) -> 0 | GW8: =SUM(FP8:FS8) -> 0 | GX8: =SUM(FT8:FX8) -> 0 | GY8: =SUM(FY8:GB8) -> 0 | GZ8: =SUM(GC8:GF8) -> 0 | HA8: =SUM(GG8:GK8) -> 0 | HB8: =SUM(GL8:GO8) -> 0
C9: =+C8+1 -> 7 | D9: 0 | E9: 0 | F9: 0 | G9: =IF(M9="","",IF(ISERROR(VLOOKUP(M9,Parametros!AI:AJ,2,0)),"Demais OOH",VLOOKUP(M9,Parametros!AI:AJ,2,0))) | J9: =IFERROR(VLOOKUP(K9,'GEOS AMBEV'!B:C,2,0),"") | K9: =_xlfn.XLOOKUP(L9,POPULAÇÃO!D:D,POPULAÇÃO!C:C) -> 0 | Q9: =IFERROR(VLOOKUP(O9,Parametros!J:K,2,0),"") | T9: =IF(R9="","",IF(R9="digital",W9&"""- "&V9&" ins/dia",TEXT(AA9,"0,00")&" x "&TEXT(AB9,"0,00")&"m")) | Y9: =IFERROR(86400/W9/24*X9,0) -> 0 | Z9: =+U9*V9 -> 0 | AF9: =IFERROR(VLOOKUP(AE9,Parametros!E:F,2,0),0) -> 0 | AJ9: =IF(AG9="","",AH9-AG9+1) | CL9: =IFERROR(COUNT(AK9:CJ9)/CK9,0) -> 0 | CM9: =IFERROR(SUM(AK9:CJ9)/CK9,0) -> 0 | CQ9: =IF(AE9="diária",CP9*AJ9*U9,IF(AJ9>AF9,CP9,AJ9/AF9*CP9)*U9) -> 0 | CR9: =IF(CN9="","0",IF(CN9="Faces",CQ9*CM9,CQ9*CL9)) -> 0 | CS9: 0.65 | CT9: =CP9*(1-CS9) -> 0 | CU9: =CR9*(1-CS9) -> 0 | CV9: =CU9*0.8 -> 0 | CW9: =IF(H9="","",IFERROR(VLOOKUP(H9,Parametros!B:C,2,0),0)) | CX9: =EG9 -> 0 | CY9: =IF(OR(CX9=0,CX9="Sem base de dados"),0,CV9/CX9*1000) -> 0 | DA9: =DK9 -> 0 | DB9: =DW9 -> 0 | DD9: =IF(AG9="",0,EDATE(DATE(YEAR(AG9),MONTH(AG9),1),5)) -> 0 | DE9: 2025 | DJ9: 800 | DK9: =DJ9*DI9*DH9 -> 0 | DM9: =IF(R9="Digital",0,IF(SUM(AK9:CJ9)=0,0,LARGE(AK9:CJ9,1))) -> 0 | DP9: =ROUNDUP(DN9*DM9*(1+DO9),0) -> 0 | DU9: =PRODUCT(DP9:DT9) -> 0 | DW9: =(DU9+DV9) -> 0 | DZ9: =SUMIFS('Mediana dos Impactos'!D:D,'Mediana dos Impactos'!C:C,OOH!O9,'Mediana dos Impactos'!B:B,OOH!L9) -> 0 | EB9: =AJ9 | EC9: =IFERROR(IF(DZ9<>"",DZ9/7*EB9,$EA9/30*EB9),0) -> 0 | ED9: =IF(DY9="",0,IF(DY9="Face",CM9,CL9)) -> 0 | EE9: =IF(DY9="Sem base de dados",DY9,EC9*ED9) -> 0 | EF9: =IF(R9="digital",(EI9*EH9),EJ9*EH9) -> 0 | EG9: =+EE9*EF9 -> 0 | EH9: =IFERROR(IF(N9="via pública",VLOOKUP($O9,Parametros!$J:$L,3,0),VLOOKUP(N9,Parametros!V:W,2,0)),0) -> 0 | EI9: =IFERROR(Z9/Y9,0) -> 0 | EJ9: =IFERROR(VLOOKUP(AC9,Parametros!AL:AM,2,0),1) -> 1 | EM9: =SUM(EP9:GO9) -> 0 | EN9: =EM9=CV9 -> TRUE | EP9: {=_xlfn.IFS(AK9="","",AK9,$CV9/$CM9/$CK9*AK9)} | EQ9: {=_xlfn.IFS(AL9="","",AL9,$CV9/$CM9/$CK9*AL9)} | ER9: {=_xlfn.IFS(AM9="","",AM9,$CV9/$CM9/$CK9*AM9)} | ES9: {=_xlfn.IFS(AN9="","",AN9,$CV9/$CM9/$CK9*AN9)} | ET9: {=_xlfn.IFS(AO9="","",AO9,$CV9/$CM9/$CK9*AO9)} | EU9: {=_xlfn.IFS(AP9="","",AP9,$CV9/$CM9/$CK9*AP9)} | EV9: {=_xlfn.IFS(AQ9="","",AQ9,$CV9/$CM9/$CK9*AQ9)} | EW9: {=_xlfn.IFS(AR9="","",AR9,$CV9/$CM9/$CK9*AR9)} | ... GO9: {=_xlfn.IFS(CJ9="","",CJ9,$CV9/$CM9/$CK9*CJ9)} | GQ9: =SUM(EP9:ES9) -> 0 | GR9: =SUM(ET9:EW9) -> 0 | GS9: =SUM(EX9:FB9) -> 0 | GT9: =SUM(FC9:FF9) -> 0 | GU9: =SUM(FG9:FK9) -> 0 | GV9: =SUM(FL9:FO9) -> 0 | GW9: =SUM(FP9:FS9) -> 0 | GX9: =SUM(FT9:FX9) -> 0 | GY9: =SUM(FY9:GB9) -> 0 | GZ9: =SUM(GC9:GF9) -> 0 | HA9: =SUM(GG9:GK9) -> 0 | HB9: =SUM(GL9:GO9) -> 0
C10: =+C9+1 -> 8 | D10: 0 | E10: 0 | F10: 0 | G10: =IF(M10="","",IF(ISERROR(VLOOKUP(M10,Parametros!AI:AJ,2,0)),"Demais OOH",VLOOKUP(M10,Parametros!AI:AJ,2,0))) | J10: =IFERROR(VLOOKUP(K10,'GEOS AMBEV'!B:C,2,0),"") | K10: =_xlfn.XLOOKUP(L10,POPULAÇÃO!D:D,POPULAÇÃO!C:C) -> 0 | Q10: =IFERROR(VLOOKUP(O10,Parametros!J:K,2,0),"") | T10: =IF(R10="","",IF(R10="digital",W10&"""- "&V10&" ins/dia",TEXT(AA10,"0,00")&" x "&TEXT(AB10,"0,00")&"m")) | Y10: =IFERROR(86400/W10/24*X10,0) -> 0 | Z10: =+U10*V10 -> 0 | AF10: =IFERROR(VLOOKUP(AE10,Parametros!E:F,2,0),0) -> 0 | AJ10: =IF(AG10="","",AH10-AG10+1) | CL10: =IFERROR(COUNT(AK10:CJ10)/CK10,0) -> 0 | CM10: =IFERROR(SUM(AK10:CJ10)/CK10,0) -> 0 | CQ10: =IF(AE10="diária",CP10*AJ10*U10,IF(AJ10>AF10,CP10,AJ10/AF10*CP10)*U10) -> 0 | CR10: =IF(CN10="","0",IF(CN10="Faces",CQ10*CM10,CQ10*CL10)) -> 0 | CS10: 0.65 | CT10: =CP10*(1-CS10) -> 0 | CU10: =CR10*(1-CS10) -> 0 | CV10: =CU10*0.8 -> 0 | CW10: =IF(H10="","",IFERROR(VLOOKUP(H10,Parametros!B:C,2,0),0)) | CX10: =EG10 -> 0 | CY10: =IF(OR(CX10=0,CX10="Sem base de dados"),0,CV10/CX10*1000) -> 0 | DA10: =DK10 -> 0 | DB10: =DW10 -> 0 | DD10: =IF(AG10="",0,EDATE(DATE(YEAR(AG10),MONTH(AG10),1),5)) -> 0 | DE10: 2025 | DJ10: 800 | DK10: =DJ10*DI10*DH10 -> 0 | DM10: =IF(R10="Digital",0,IF(SUM(AK10:CJ10)=0,0,LARGE(AK10:CJ10,1))) -> 0 | DP10: =ROUNDUP(DN10*DM10*(1+DO10),0) -> 0 | DU10: =PRODUCT(DP10:DT10) -> 0 | DW10: =(DU10+DV10) -> 0 | DZ10: =SUMIFS('Mediana dos Impactos'!D:D,'Mediana dos Impactos'!C:C,OOH!O10,'Mediana dos Impactos'!B:B,OOH!L10) -> 0 | EB10: =AJ10 | EC10: =IFERROR(IF(DZ10<>"",DZ10/7*EB10,$EA10/30*EB10),0) -> 0 | ED10: =IF(DY10="",0,IF(DY10="Face",CM10,CL10)) -> 0 | EE10: =IF(DY10="Sem base de dados",DY10,EC10*ED10) -> 0 | EF10: =IF(R10="digital",(EI10*EH10),EJ10*EH10) -> 0 | EG10: =+EE10*EF10 -> 0 | EH10: =IFERROR(IF(N10="via pública",VLOOKUP($O10,Parametros!$J:$L,3,0),VLOOKUP(N10,Parametros!V:W,2,0)),0) -> 0 | EI10: =IFERROR(Z10/Y10,0) -> 0 | EJ10: =IFERROR(VLOOKUP(AC10,Parametros!AL:AM,2,0),1) -> 1 | EM10: =SUM(EP10:GO10) -> 0 | EN10: =EM10=CV10 -> TRUE | EP10: {=_xlfn.IFS(AK10="","",AK10,$CV10/$CM10/$CK10*AK10)} | EQ10: {=_xlfn.IFS(AL10="","",AL10,$CV10/$CM10/$CK10*AL10)} | ER10: {=_xlfn.IFS(AM10="","",AM10,$CV10/$CM10/$CK10*AM10)} | ES10: {=_xlfn.IFS(AN10="","",AN10,$CV10/$CM10/$CK10*AN10)} | ET10: {=_xlfn.IFS(AO10="","",AO10,$CV10/$CM10/$CK10*AO10)} | EU10: {=_xlfn.IFS(AP10="","",AP10,$CV10/$CM10/$CK10*AP10)} | EV10: {=_xlfn.IFS(AQ10="","",AQ10,$CV10/$CM10/$CK10*AQ10)} | EW10: {=_xlfn.IFS(AR10="","",AR10,$CV10/$CM10/$CK10*AR10)} | ... GO10: {=_xlfn.IFS(CJ10="","",CJ10,$CV10/$CM10/$CK10*CJ10)} | GQ10: =SUM(EP10:ES10) -> 0 | GR10: =SUM(ET10:EW10) -> 0 | GS10: =SUM(EX10:FB10) -> 0 | GT10: =SUM(FC10:FF10) -> 0 | GU10: =SUM(FG10:FK10) -> 0 | GV10: =SUM(FL10:FO10) -> 0 | GW10: =SUM(FP10:FS10) -> 0 | GX10: =SUM(FT10:FX10) -> 0 | GY10: =SUM(FY10:GB10) -> 0 | GZ10: =SUM(GC10:GF10) -> 0 | HA10: =SUM(GG10:GK10) -> 0 | HB10: =SUM(GL10:GO10) -> 0
C11: =+C10+1 -> 9 | D11: 0 | E11: 0 | F11: 0 | G11: =IF(M11="","",IF(ISERROR(VLOOKUP(M11,Parametros!AI:AJ,2,0)),"Demais OOH",VLOOKUP(M11,Parametros!AI:AJ,2,0))) | J11: =IFERROR(VLOOKUP(K11,'GEOS AMBEV'!B:C,2,0),"") | K11: =_xlfn.XLOOKUP(L11,[39]POPULAÇÃO!D:D,[39]POPULAÇÃO!C:C) -> 0 | Q11: =IFERROR(VLOOKUP(O11,[39]Parametros!J:K,2,0),"") | T11: =IF(R11="","",IF(R11="digital",W11&"""- "&V11&" ins/dia",TEXT(AA11,"0,00")&" x "&TEXT(AB11,"0,00")&"m")) | Y11: =IFERROR(86400/W11/24*X11,0) -> 0 | Z11: =+U11*V11 -> 0 | AF11: =IFERROR(VLOOKUP(AE11,Parametros!E:F,2,0),0) -> 0 | AJ11: =IF(AG11="","",AH11-AG11+1) | CL11: =IFERROR(COUNT(AK11:CJ11)/CK11,0) -> 0 | CM11: =IFERROR(SUM(AK11:CJ11)/CK11,0) -> 0 | CQ11: =IF(AE11="diária",CP11*AJ11*U11,IF(AJ11>AF11,CP11,AJ11/AF11*CP11)*U11) -> 0 | CR11: =IF(CN11="","0",IF(CN11="Faces",CQ11*CM11,CQ11*CL11)) -> 0 | CS11: 0.65 | CT11: =CP11*(1-CS11) -> 0 | CU11: =CR11*(1-CS11) -> 0 | CV11: =CU11*0.8 -> 0 | CW11: =IF(H11="","",IFERROR(VLOOKUP(H11,[39]Parametros!B:C,2,0),0)) | CX11: =EG11 -> 0 | CY11: =IF(OR(CX11=0,CX11="Sem base de dados"),0,CV11/CX11*1000) -> 0 | DA11: =DK11 -> 0 | DB11: =DW11 -> 0 | DD11: =IF(AG11="",0,EDATE(DATE(YEAR(AG11),MONTH(AG11),1),5)) -> 0 | DE11: 2025 | DJ11: 800 | DK11: =DJ11*DI11*DH11 -> 0 | DM11: =IF(R11="Digital",0,IF(SUM(AK11:CJ11)=0,0,LARGE(AK11:CJ11,1))) -> 0 | DP11: =ROUNDUP(DN11*DM11*(1+DO11),0) -> 0 | DU11: =PRODUCT(DP11:DT11) -> 0 | DW11: =(DU11+DV11) -> 0 | DZ11: =SUMIFS('Mediana dos Impactos'!D:D,'Mediana dos Impactos'!C:C,OOH!O11,'Mediana dos Impactos'!B:B,OOH!L11) -> 0 | EB11: =AJ11 | EC11: =IFERROR(IF(DZ11<>"",DZ11/7*EB11,$EA11/30*EB11),0) -> 0 | ED11: =IF(DY11="",0,IF(DY11="Face",CM11,CL11)) -> 0 | EE11: =IF(DY11="Sem base de dados",DY11,EC11*ED11) -> 0 | EF11: =IF(R11="digital",(EI11*EH11),EJ11*EH11) -> 0 | EG11: =+EE11*EF11 -> 0 | EH11: =IFERROR(IF(N11="via pública",VLOOKUP($O11,Parametros!$J:$L,3,0),VLOOKUP(N11,Parametros!V:W,2,0)),0) -> 0 | EI11: =IFERROR(Z11/Y11,0) -> 0 | EJ11: =IFERROR(VLOOKUP(AC11,Parametros!AL:AM,2,0),1) -> 1 | EM11: =SUM(EP11:GO11) -> 0 | EN11: =EM11=CV11 -> TRUE | EP11: {=_xlfn.IFS(AK11="","",AK11,$CV11/$CM11/$CK11*AK11)} | EQ11: {=_xlfn.IFS(AL11="","",AL11,$CV11/$CM11/$CK11*AL11)} | ER11: {=_xlfn.IFS(AM11="","",AM11,$CV11/$CM11/$CK11*AM11)} | ES11: {=_xlfn.IFS(AN11="","",AN11,$CV11/$CM11/$CK11*AN11)} | ET11: {=_xlfn.IFS(AO11="","",AO11,$CV11/$CM11/$CK11*AO11)} | EU11: {=_xlfn.IFS(AP11="","",AP11,$CV11/$CM11/$CK11*AP11)} | EV11: {=_xlfn.IFS(AQ11="","",AQ11,$CV11/$CM11/$CK11*AQ11)} | EW11: {=_xlfn.IFS(AR11="","",AR11,$CV11/$CM11/$CK11*AR11)} | ... GO11: {=_xlfn.IFS(CJ11="","",CJ11,$CV11/$CM11/$CK11*CJ11)} | GQ11: =SUM(EP11:ES11) -> 0 | GR11: =SUM(ET11:EW11) -> 0 | GS11: =SUM(EX11:FB11) -> 0 | GT11: =SUM(FC11:FF11) -> 0 | GU11: =SUM(FG11:FK11) -> 0 | GV11: =SUM(FL11:FO11) -> 0 | GW11: =SUM(FP11:FS11) -> 0 | GX11: =SUM(FT11:FX11) -> 0 | GY11: =SUM(FY11:GB11) -> 0 | GZ11: =SUM(GC11:GF11) -> 0 | HA11: =SUM(GG11:GK11) -> 0 | HB11: =SUM(GL11:GO11) -> 0
C12: =+C11+1 -> 10 | D12: 0 | E12: 0 | F12: 0 | G12: =IF(M12="","",IF(ISERROR(VLOOKUP(M12,Parametros!AI:AJ,2,0)),"Demais OOH",VLOOKUP(M12,Parametros!AI:AJ,2,0))) | J12: =IFERROR(VLOOKUP(K12,'GEOS AMBEV'!B:C,2,0),"") | K12: =_xlfn.XLOOKUP(L12,POPULAÇÃO!D:D,POPULAÇÃO!C:C) -> 0 | Q12: =IFERROR(VLOOKUP(O12,Parametros!J:K,2,0),"") | T12: =IF(R12="","",IF(R12="digital",W12&"""- "&V12&" ins/dia",TEXT(AA12,"0,00")&" x "&TEXT(AB12,"0,00")&"m")) | Y12: =IFERROR(86400/W12/24*X12,0) -> 0 | Z12: =+U12*V12 -> 0 | AF12: =IFERROR(VLOOKUP(AE12,Parametros!E:F,2,0),0) -> 0 | AJ12: =IF(AG12="","",AH12-AG12+1) | CL12: =IFERROR(COUNT(AK12:CJ12)/CK12,0) -> 0 | CM12: =IFERROR(SUM(AK12:CJ12)/CK12,0) -> 0 | CQ12: =IF(AE12="diária",CP12*AJ12*U12,IF(AJ12>AF12,CP12,AJ12/AF12*CP12)*U12) -> 0 | CR12: =IF(CN12="","0",IF(CN12="Faces",CQ12*CM12,CQ12*CL12)) -> 0 | CS12: 0.7 | CT12: =CP12*(1-CS12) -> 0 | CU12: =CR12*(1-CS12) -> 0 | CV12: =CU12*0.8 -> 0 | CW12: =IF(H12="","",IFERROR(VLOOKUP(H12,Parametros!B:C,2,0),0)) | CX12: =EG12 -> 0 | CY12: =IF(OR(CX12=0,CX12="Sem base de dados"),0,CV12/CX12*1000) -> 0 | DA12: =DK12 -> 0 | DB12: =DW12 -> 0 | DD12: =IF(AG12="",0,EDATE(DATE(YEAR(AG12),MONTH(AG12),1),5)) -> 0 | DE12: 2025 | DJ12: 800 | DK12: =DJ12*DI12*DH12 -> 0 | DM12: =IF(R12="Digital",0,IF(SUM(AK12:CJ12)=0,0,LARGE(AK12:CJ12,1))) -> 0 | DP12: =ROUNDUP(DN12*DM12*(1+DO12),0) -> 0 | DU12: =PRODUCT(DP12:DT12) -> 0 | DW12: =(DU12+DV12) -> 0 | DZ12: =SUMIFS('Mediana dos Impactos'!D:D,'Mediana dos Impactos'!C:C,OOH!O12,'Mediana dos Impactos'!B:B,OOH!L12) -> 0 | EB12: =AJ12 | EC12: =IFERROR(IF(DZ12<>"",DZ12/7*EB12,$EA12/30*EB12),0) -> 0 | ED12: =IF(DY12="",0,IF(DY12="Face",CM12,CL12)) -> 0 | EE12: =IF(DY12="Sem base de dados",DY12,EC12*ED12) -> 0 | EF12: =IF(R12="digital",(EI12*EH12),EJ12*EH12) -> 0 | EG12: =+EE12*EF12 -> 0 | EH12: =IFERROR(IF(N12="via pública",VLOOKUP($O12,Parametros!$J:$L,3,0),VLOOKUP(N12,Parametros!V:W,2,0)),0) -> 0 | EI12: =IFERROR(Z12/Y12,0) -> 0 | EJ12: =IFERROR(VLOOKUP(AC12,Parametros!AL:AM,2,0),1) -> 1 | EM12: =SUM(EP12:GO12) -> 0 | EN12: =EM12=CV12 -> TRUE | EP12: {=_xlfn.IFS(AK12="","",AK12,$CV12/$CM12/$CK12*AK12)} | EQ12: {=_xlfn.IFS(AL12="","",AL12,$CV12/$CM12/$CK12*AL12)} | ER12: {=_xlfn.IFS(AM12="","",AM12,$CV12/$CM12/$CK12*AM12)} | ES12: {=_xlfn.IFS(AN12="","",AN12,$CV12/$CM12/$CK12*AN12)} | ET12: {=_xlfn.IFS(AO12="","",AO12,$CV12/$CM12/$CK12*AO12)} | EU12: {=_xlfn.IFS(AP12="","",AP12,$CV12/$CM12/$CK12*AP12)} | EV12: {=_xlfn.IFS(AQ12="","",AQ12,$CV12/$CM12/$CK12*AQ12)} | EW12: {=_xlfn.IFS(AR12="","",AR12,$CV12/$CM12/$CK12*AR12)} | ... GO12: {=_xlfn.IFS(CJ12="","",CJ12,$CV12/$CM12/$CK12*CJ12)} | GQ12: =SUM(EP12:ES12) -> 0 | GR12: =SUM(ET12:EW12) -> 0 | GS12: =SUM(EX12:FB12) -> 0 | GT12: =SUM(FC12:FF12) -> 0 | GU12: =SUM(FG12:FK12) -> 0 | GV12: =SUM(FL12:FO12) -> 0 | GW12: =SUM(FP12:FS12) -> 0 | GX12: =SUM(FT12:FX12) -> 0 | GY12: =SUM(FY12:GB12) -> 0 | GZ12: =SUM(GC12:GF12) -> 0 | HA12: =SUM(GG12:GK12) -> 0 | HB12: =SUM(GL12:GO12) -> 0
